<?xml version="1.0" ?><!-- =================================================================================== --><!-- |    This document was autogenerated by xacro from /home/pal/deployed_ws/tiago_pro_description/share/tiago_pro_description/robots/tiago_pro.urdf.xacro | --><!-- |    EDITING THIS FILE BY HAND IS NOT RECOMMENDED                                 | --><!-- =================================================================================== --><!--

  Copyright (c) 2024 PAL Robotics S.L. All rights reserved.
  Licensed under the Apache License, Version 2.0 (the "License");
  you may not use this file except in compliance with the License.
  You may obtain a copy of the License at

      http://www.apache.org/licenses/LICENSE-2.0

  Unless required by applicable law or agreed to in writing, software
  distributed under the License is distributed on an "AS IS" BASIS,
  WITHOUT WARRANTIES OR CONDITIONS OF ANY KIND, either express or implied.
  See the License for the specific language governing permissions and
  limitations under the License.
--><robot name="tiago_pro" xmlns:gz="http://gazebosim.org/schema"><!-- ARGUMENTS --><!-- PROPERTIES --><!-- Compatibility check within TC and ft sensors--><!-- <xacro:if value="${ft_sensor_right == 'ati' and wrist_model_right=='straight-wrist'}">
    <xacro:error_ati_not_compatible_with_straight_wrist />
  </xacro:if>
  <xacro:if value="${ft_sensor_left == 'ati' and wrist_model_left=='straight-wrist'}">
    <xacro:error_ati_not_compatible_with_straight_wrist />
  </xacro:if>
  <xacro:if value="${ft_sensor_right == 'rokubi' and wrist_model_right=='spherical-wrist'}">
    <xacro:error_rokubi_not_compatible_with_spherical_wrist />
  </xacro:if>
  <xacro:if value="${ft_sensor_left == 'rokubi' and wrist_model_left=='spherical-wrist'}">
    <xacro:error_rokubi_not_compatible_with_spherical_wrist />
  </xacro:if>
  <xacro:if value="${ft_sensor_right == 'rokubi' and tool_changer_right}">
    <xacro:error_rokubi_not_compatible_with_tc />
  </xacro:if>
  <xacro:if value="${ft_sensor_left == 'rokubi' and tool_changer_left}">
    <xacro:error_rokubi_not_compatible_with_tc />
  </xacro:if>
  <xacro:if value="${not tool_changer_right and wrist_model_right=='spherical-wrist'}">
    <xacro:error_spherical_wrist_always_comes_with_tc />
  </xacro:if>
  <xacro:if value="${not tool_changer_left and wrist_model_left=='spherical-wrist'}">
    <xacro:error_spherical_wrist_always_comes_with_tc />
  </xacro:if>
  <xacro:if value="${not tool_changer_left and ft_sensor_left == 'ati'}">
    <xacro:error_ati_always_comes_with_tc />
  </xacro:if>
  <xacro:if value="${not tool_changer_right and ft_sensor_right == 'ati'}">
    <xacro:error_ati_always_comes_with_tc />
  </xacro:if> --><!-- INCLUDES --><!-- PROPERTIES --><material name="aluminum"><color rgba="0.5 0.5 0.5 1"/></material><material name="plastic"><color rgba="0.1 0.1 0.1 1"/></material><!-- EYE FRAMES --><link name="sellion_link"/><joint name="sellion_joint" type="fixed"><origin rpy="1.5708 0 0" xyz="0.04 -0.09205 0"/><child link="sellion_link"/><parent link="head_2_link"/></joint><link name="eye_right_link"/><joint name="eye_right_joint" type="fixed"><origin rpy="0 0 0" xyz="0.0 -0.1 0"/><child link="eye_right_link"/><parent link="sellion_link"/></joint><link name="eye_left_link"/><joint name="eye_left_joint" type="fixed"><origin rpy="0 0 0" xyz="0 0.1 0"/><child link="eye_left_link"/><parent link="sellion_link"/></joint><link name="head_front_camera_color_eye_frame"/><joint name="color_eye_joint" type="fixed"><origin rpy="-1.571 0.000 -1.571" xyz="0.000 0.000 0.000"/><child link="head_front_camera_color_eye_frame"/><parent link="head_front_camera_link"/></joint><material name="Blue"><color rgba="0.0 0.0 0.8 1.0"/></material><material name="Green"><color rgba="0.0 0.8 0.0 1.0"/></material><material name="Grey"><color rgba="0.7 0.7 0.7 1.0"/></material><material name="LightGrey"><color rgba="0.9 0.9 0.9 1.0"/></material><material name="DarkGrey"><color rgba="0.1 0.1 0.1 1.0"/></material><material name="Red"><color rgba="0.8 0.0 0.0 1.0"/></material><material name="White"><color rgba="1.0 1.0 1.0 1.0"/></material><material name="Yellow"><color rgba="0.96 0.88 0.14 1.0"/></material><material name="Black"><color rgba="0.0 0.0 0.0 1.0"/></material><material name="FlatBlack"><color rgba="0.09 0.09 0.09 1.0"/></material><material name="Orange"><color rgba="1.0 0.487 0.0 1.0"/></material><material name="pal/Orange"><color rgba="0.91373 0.61568 0.29411 1.0"/></material><material name="pal/DarkGrey"><color rgba="0.29804 0.29804 0.29804 1"/></material><!-- ROBOT DEFINITION --><!-- Virtual Base Laser Link --><joint name="virtual_base_laser_joint" type="fixed"><parent link="base_link"/><child link="virtual_base_laser_link"/><origin rpy="0 0 0" xyz="0 0 0.13244"/></joint><link name="virtual_base_laser_link"/><link name="base_imu_link"/><joint name="base_imu_joint" type="fixed"><parent link="base_link"/><child link="base_imu_link"/><origin rpy="0 0 1.5707963267948966" xyz="-0.287 0 0.092163"/></joint><gazebo reference="base_imu_link"><sensor name="base_imu_sensor" type="imu"><always_on>1</always_on><update_rate>100.0</update_rate><topic>base_imu</topic><imu><noise><type>gaussian</type><rate><mean>0.0</mean><stddev>2e-4</stddev><bias_mean>0.0000075</bias_mean><bias_stddev>0.0000008</bias_stddev></rate><accel><mean>0.0</mean><stddev>1.7e-2</stddev><bias_mean>0.1</bias_mean><bias_stddev>0.001</bias_stddev></accel></noise></imu><plugin filename="libgazebo_ros_imu_sensor.so" name="base_imu"><ros><namespace></namespace><!-- publish to /imu/data --><remapping>~/out:=base_imu</remapping></ros></plugin></sensor></gazebo><!-- Base --><link name="base_link"><inertial><origin rpy="0 0 0" xyz="0.0026742 0.00027459 0.086363"/><mass value="34.047"/><inertia ixx="0.22777" ixy="0.00035979" ixz="0.00015269" iyy="0.29991" iyz="1.7872E-05" izz="0.46036"/></inertial><visual><origin rpy="0 0 0" xyz="0 0 0"/><geometry><mesh filename="package://omni_base_description/meshes/base/base_link.stl"/></geometry><material name=""><color rgba="0.75294 0.75294 0.75294 1"/></material></visual><collision><origin rpy="0 0 0" xyz="0 0 0.18925"/><geometry><box size="0.717 0.497 0.0845"/></geometry></collision><collision><origin rpy="0 0 0" xyz="0 0 0.132"/><geometry><box size="0.58 0.39 0.03"/></geometry></collision><collision><origin rpy="0 0 0" xyz="0 0 0.0335"/><geometry><box size="0.705 0.48 0.167"/></geometry></collision></link><!-- Base footprint --><link name="base_footprint"/><joint name="base_footprint_joint" type="fixed"><origin rpy="0 0 0" xyz="0 0 0.0762"/><child link="base_link"/><parent link="base_footprint"/></joint><!-- Docking link --><link name="base_dock_link"><inertial><origin rpy="0 0 0" xyz="-0.0037082 1.5226E-18 -4.1633E-17"/><mass value="0.032242"/><inertia ixx="2.1302E-05" ixy="-1.0461E-21" ixz="6.6555E-22" iyy="1.2058E-05" iyz="-1.9453E-21" izz="1.0058E-05"/></inertial><visual><origin rpy="0 0 0" xyz="0 0 0"/><geometry><mesh filename="package://omni_base_description/meshes/base/base_dock_link.stl"/></geometry><material name=""><color rgba="0.25098 0.25098 0.25098 1"/></material></visual><collision><origin rpy="0 0 0" xyz="0 0 0"/><geometry><mesh filename="package://omni_base_description/meshes/base/base_dock_link.stl"/></geometry></collision></link><joint name="base_dock" type="fixed"><origin rpy="0 0 0" xyz="0.3535 0 0.0596"/><parent link="base_link"/><child link="base_dock_link"/><axis xyz="0 0 0"/></joint><link name="base_antenna_right_link"><inertial><origin rpy="0 0 0" xyz="0.027807 -0.0085125 0.015138"/><mass value="0.02311"/><inertia ixx="2.3107E-06" ixy="5.0914e-06" ixz="8.5605E-08" iyy="1.7384E-05" iyz="-2.6206e-08" izz="1.8542E-05"/></inertial><visual><origin rpy="0 0 0" xyz="0 0 0"/><geometry><mesh filename="package://omni_base_description/meshes/base/base_antena_link.stl" scale="1 1 1"/></geometry><material name=""><color rgba="0.75294 0.75294 0.75294 1"/></material></visual><collision><origin rpy="0 0 0" xyz="0 0 0"/><geometry><mesh filename="package://omni_base_description/meshes/base/base_antena_link.stl" scale="1 1 1"/></geometry></collision></link><joint name="base_antenna_right_joint" type="fixed"><origin rpy="0 0 0" xyz="-0.2015 -0.13 0.2165"/><parent link="base_link"/><child link="base_antenna_right_link"/><axis xyz="0 0 0"/></joint><gazebo reference="base_antenna_right_link"><material>Gazebo/Black</material></gazebo><link name="base_antenna_left_link"><inertial><origin rpy="0 0 0" xyz="0.027807 0.0085125 0.015138"/><mass value="0.02311"/><inertia ixx="2.3107E-06" ixy="-5.0914e-06" ixz="8.5605E-08" iyy="1.7384E-05" iyz="2.6206e-08" izz="1.8542E-05"/></inertial><visual><origin rpy="0 0 0" xyz="0 0 0"/><geometry><mesh filename="package://omni_base_description/meshes/base/base_antena_link.stl" scale="1 -1 1"/></geometry><material name=""><color rgba="0.75294 0.75294 0.75294 1"/></material></visual><collision><origin rpy="0 0 0" xyz="0 0 0"/><geometry><mesh filename="package://omni_base_description/meshes/base/base_antena_link.stl" scale="1 -1 1"/></geometry></collision></link><joint name="base_antenna_left_joint" type="fixed"><origin rpy="0 0 0" xyz="-0.2015 0.13 0.2165"/><parent link="base_link"/><child link="base_antenna_left_link"/><axis xyz="0 0 0"/></joint><gazebo reference="base_antenna_left_link"><material>Gazebo/Black</material></gazebo><link name="suspension_front_right_link"><inertial><origin rpy="0 0 0" xyz="-0.058182 -0.0043908 -0.0057695"/><mass value="1.2879"/><inertia ixx="0.0015947" ixy="-0.00013183" ixz="1.7315E-05" iyy="0.00060158" iyz="-6.0731e-05" izz="0.0015861"/></inertial><visual><origin rpy="0 0 0" xyz="0 0 0"/><geometry><mesh filename="package://omni_base_description/meshes/wheels/suspension_front_link.stl" scale="1 1.0 1"/></geometry><material name=""><color rgba="0.79216 0.81961 0.93333 1"/></material></visual><collision><origin rpy="0 0 0" xyz="0 0 0"/><geometry><mesh filename="package://omni_base_description/meshes/wheels/suspension_front_link.stl" scale="1 1.0 1"/></geometry></collision><kinematic>0</kinematic><gravity>1</gravity></link><!-- Changed joint type to fixed joint. It is observed that the robot is loosing contact points due to some issues with the Gazebo Physics Engine. This makes the robot drift in localization when static due to added noise --><joint name="suspension_front_right_joint" type="fixed"><origin rpy="0 0 -1.5707963267948966" xyz="0.244 -0.1725 0"/><parent link="base_link"/><child link="suspension_front_right_link"/><axis xyz="0 0 1"/></joint><link name="wheel_front_right_link"><inertial><origin rpy="0 0 0" xyz="5.4922e-09 6.9775e-05 0.011144"/><mass value="0.70767"/><inertia ixx="0.00035492" ixy="7.5685e-13" ixz="3.8795E-11" iyy="0.00035529" iyz="-2.0284e-07" izz="0.00040131"/></inertial><visual><origin rpy="0 0 0" xyz="0 0 0"/><geometry><mesh filename="package://omni_base_description/meshes/wheels/wheel_link.stl" scale="1 1 1.0"/></geometry><material name="DarkGrey"/></visual><collision><origin rpy="0 0 0" xyz="0 0 0"/><geometry><cylinder length="0.05" radius="0.0762"/></geometry></collision></link><joint name="wheel_front_right_joint" type="continuous"><origin rpy="-1.5707963267948966 0 1.5707963267948966" xyz="0.050675 0 0"/><parent link="suspension_front_right_link"/><child link="wheel_front_right_link"/><axis xyz="0 0 1"/><limit effort="6.0" velocity="100.0"/><dynamics damping="1.0" friction="2.0"/></joint><!-- Contact model for the wheel surface --><gazebo reference="wheel_front_right_link"><kp>1000000.0</kp><kd>1000.0</kd><mu1>0.0</mu1><mu2>0.0</mu2><fdir1>1 0 0</fdir1><maxVel>1.0</maxVel><minDepth>0.00</minDepth><implicitSpringDamper>1</implicitSpringDamper><material>Gazebo/Grey</material></gazebo><link name="suspension_front_left_link"><inertial><origin rpy="0 0 0" xyz="-0.058182 0.0043908 -0.0057695"/><mass value="1.2879"/><inertia ixx="0.0015947" ixy="0.00013183" ixz="1.7315E-05" iyy="0.00060158" iyz="6.0731e-05" izz="0.0015861"/></inertial><visual><origin rpy="0 0 0" xyz="0 0 0"/><geometry><mesh filename="package://omni_base_description/meshes/wheels/suspension_front_link.stl" scale="1 -1.0 1"/></geometry><material name=""><color rgba="0.79216 0.81961 0.93333 1"/></material></visual><collision><origin rpy="0 0 0" xyz="0 0 0"/><geometry><mesh filename="package://omni_base_description/meshes/wheels/suspension_front_link.stl" scale="1 -1.0 1"/></geometry></collision><kinematic>0</kinematic><gravity>1</gravity></link><!-- Changed joint type to fixed joint. It is observed that the robot is loosing contact points due to some issues with the Gazebo Physics Engine. This makes the robot drift in localization when static due to added noise --><joint name="suspension_front_left_joint" type="fixed"><origin rpy="0 0 1.5707963267948966" xyz="0.244 0.1725 0"/><parent link="base_link"/><child link="suspension_front_left_link"/><axis xyz="0 0 1"/></joint><link name="wheel_front_left_link"><inertial><origin rpy="0 0 0" xyz="5.4922e-09 -6.9775e-05 -0.011144"/><mass value="0.70767"/><inertia ixx="0.00035492" ixy="7.5685e-13" ixz="3.8795E-11" iyy="0.00035529" iyz="-2.0284e-07" izz="0.00040131"/></inertial><visual><origin rpy="0 0 0" xyz="0 0 0"/><geometry><mesh filename="package://omni_base_description/meshes/wheels/wheel_link.stl" scale="1 1 -1.0"/></geometry><material name="DarkGrey"/></visual><collision><origin rpy="0 0 0" xyz="0 0 0"/><geometry><cylinder length="0.05" radius="0.0762"/></geometry></collision></link><joint name="wheel_front_left_joint" type="continuous"><origin rpy="-1.5707963267948966 0 -1.5707963267948966" xyz="0.050675 0 0"/><parent link="suspension_front_left_link"/><child link="wheel_front_left_link"/><axis xyz="0 0 1"/><limit effort="6.0" velocity="100.0"/><dynamics damping="1.0" friction="2.0"/></joint><!-- Contact model for the wheel surface --><gazebo reference="wheel_front_left_link"><kp>1000000.0</kp><kd>1000.0</kd><mu1>0.0</mu1><mu2>0.0</mu2><fdir1>1 0 0</fdir1><maxVel>1.0</maxVel><minDepth>0.00</minDepth><implicitSpringDamper>1</implicitSpringDamper><material>Gazebo/Grey</material></gazebo><link name="suspension_rear_right_link"><inertial><origin rpy="0 0 0" xyz="-0.058182 0.0043908 -0.0057695"/><mass value="1.2879"/><inertia ixx="0.0015947" ixy="0.00013183" ixz="1.7315E-05" iyy="0.00060158" iyz="6.0731e-05" izz="0.0015861"/></inertial><visual><origin rpy="0 0 0" xyz="0 0 0"/><geometry><mesh filename="package://omni_base_description/meshes/wheels/suspension_rear_link.stl" scale="1 1.0 1"/></geometry><material name=""><color rgba="0.79216 0.81961 0.93333 1"/></material></visual><collision><origin rpy="0 0 0" xyz="0 0 0"/><geometry><mesh filename="package://omni_base_description/meshes/wheels/suspension_rear_link.stl" scale="1 1.0 1"/></geometry></collision><kinematic>0</kinematic><gravity>1</gravity></link><!-- Changed joint type to fixed joint. It is observed that the robot is loosing contact points due to some issues with the Gazebo Physics Engine. This makes the robot drift in localization when static due to added noise --><joint name="suspension_rear_right_joint" type="fixed"><origin rpy="0 0 -1.5707963267948966" xyz="-0.244 -0.1725 0"/><parent link="base_link"/><child link="suspension_rear_right_link"/><axis xyz="0 0 1"/></joint><link name="wheel_rear_right_link"><inertial><origin rpy="0 0 0" xyz="-5.4922e-09 -6.9775e-05 0.011144"/><mass value="0.70767"/><inertia ixx="0.00035492" ixy="-7.5685e-13" ixz="3.8795E-11" iyy="0.00035529" iyz="2.0284e-07" izz="0.00040131"/></inertial><visual><origin rpy="0 0 0" xyz="0 0 0"/><geometry><mesh filename="package://omni_base_description/meshes/wheels/wheel_link.stl" scale="1 1 1.0"/></geometry><material name="DarkGrey"/></visual><collision><origin rpy="0 0 0" xyz="0 0 0"/><geometry><cylinder length="0.05" radius="0.0762"/></geometry></collision></link><joint name="wheel_rear_right_joint" type="continuous"><origin rpy="-1.5707963267948966 0 1.5707963267948966" xyz="0.050675 0 0"/><parent link="suspension_rear_right_link"/><child link="wheel_rear_right_link"/><axis xyz="0 0 1"/><limit effort="6.0" velocity="100.0"/><dynamics damping="1.0" friction="2.0"/></joint><!-- Contact model for the wheel surface --><gazebo reference="wheel_rear_right_link"><kp>1000000.0</kp><kd>1000.0</kd><mu1>0.0</mu1><mu2>0.0</mu2><fdir1>1 0 0</fdir1><maxVel>1.0</maxVel><minDepth>0.00</minDepth><implicitSpringDamper>1</implicitSpringDamper><material>Gazebo/Grey</material></gazebo><link name="suspension_rear_left_link"><inertial><origin rpy="0 0 0" xyz="-0.058182 -0.0043908 -0.0057695"/><mass value="1.2879"/><inertia ixx="0.0015947" ixy="-0.00013183" ixz="1.7315E-05" iyy="0.00060158" iyz="-6.0731e-05" izz="0.0015861"/></inertial><visual><origin rpy="0 0 0" xyz="0 0 0"/><geometry><mesh filename="package://omni_base_description/meshes/wheels/suspension_rear_link.stl" scale="1 -1.0 1"/></geometry><material name=""><color rgba="0.79216 0.81961 0.93333 1"/></material></visual><collision><origin rpy="0 0 0" xyz="0 0 0"/><geometry><mesh filename="package://omni_base_description/meshes/wheels/suspension_rear_link.stl" scale="1 -1.0 1"/></geometry></collision><kinematic>0</kinematic><gravity>1</gravity></link><!-- Changed joint type to fixed joint. It is observed that the robot is loosing contact points due to some issues with the Gazebo Physics Engine. This makes the robot drift in localization when static due to added noise --><joint name="suspension_rear_left_joint" type="fixed"><origin rpy="0 0 1.5707963267948966" xyz="-0.244 0.1725 0"/><parent link="base_link"/><child link="suspension_rear_left_link"/><axis xyz="0 0 1"/></joint><link name="wheel_rear_left_link"><inertial><origin rpy="0 0 0" xyz="-5.4922e-09 6.9775e-05 -0.011144"/><mass value="0.70767"/><inertia ixx="0.00035492" ixy="-7.5685e-13" ixz="3.8795E-11" iyy="0.00035529" iyz="2.0284e-07" izz="0.00040131"/></inertial><visual><origin rpy="0 0 0" xyz="0 0 0"/><geometry><mesh filename="package://omni_base_description/meshes/wheels/wheel_link.stl" scale="1 1 -1.0"/></geometry><material name="DarkGrey"/></visual><collision><origin rpy="0 0 0" xyz="0 0 0"/><geometry><cylinder length="0.05" radius="0.0762"/></geometry></collision></link><joint name="wheel_rear_left_joint" type="continuous"><origin rpy="-1.5707963267948966 0 -1.5707963267948966" xyz="0.050675 0 0"/><parent link="suspension_rear_left_link"/><child link="wheel_rear_left_link"/><axis xyz="0 0 1"/><limit effort="6.0" velocity="100.0"/><dynamics damping="1.0" friction="2.0"/></joint><!-- Contact model for the wheel surface --><gazebo reference="wheel_rear_left_link"><kp>1000000.0</kp><kd>1000.0</kd><mu1>0.0</mu1><mu2>0.0</mu2><fdir1>1 0 0</fdir1><maxVel>1.0</maxVel><minDepth>0.00</minDepth><implicitSpringDamper>1</implicitSpringDamper><material>Gazebo/Grey</material></gazebo><!-- Materials --><gazebo reference="base_link"><material>Gazebo/White</material></gazebo><!-- base_link through base_footprint--><gazebo reference="base_footprint"><kp>100000000.0</kp><kd>10.0</kd><mu1>0.1</mu1><mu2>0.1</mu2><fdir1>1 0 0</fdir1><maxVel>10.0</maxVel><minDepth>0.0005</minDepth><laserRetro>0</laserRetro></gazebo><!-- Odometry plugin for ground truth --><gazebo><plugin filename="libgazebo_ros_planar_move.so" name="gazebo_ros_planar_move"><ros><namespace></namespace><remapping>cmd_vel:=mobile_base_controller/cmd_vel_unstamped</remapping><remapping>odom:=mobile_base_controller/odom</remapping></ros><update_rate>100</update_rate><publish_rate>1000</publish_rate><publish_odom>true</publish_odom><publish_odom_tf>false</publish_odom_tf><odometry_frame>odom</odometry_frame><robot_base_frame>base_footprint</robot_base_frame><covariance_x>0.0001</covariance_x><covariance_y>0.0001</covariance_y><covariance_yaw>0.01</covariance_yaw></plugin></gazebo><!-- Connection with the base --><link name="torso_base_link"><inertial><origin rpy="0 0 0" xyz="-0.043624513712351 -5.47054746000779E-05 0.0277532809798974"/><mass value="1.00223030186675"/><inertia ixx="0.00660602943010985" ixy="3.32767644990319E-05" ixz="-0.000408545705396379" iyy="0.00690807320580873" iyz="8.29177467923023E-06" izz="0.0122016808119362"/></inertial><visual><origin rpy="0 0 0" xyz="0 0 0"/><geometry><mesh filename="package://tiago_pro_description/meshes/torso/torso_fixed.stl"/></geometry><material name="pal/DarkGrey"/></visual><collision><origin rpy="0 0 0" xyz="0 0 0"/><geometry><mesh filename="package://tiago_pro_description/meshes/torso/torso_fixed_collision.stl"/></geometry></collision></link><joint name="torso_fixed_joint" type="fixed"><origin rpy="0 0 0" xyz="-0.0245 0 0.215"/><parent link="base_link"/><child link="torso_base_link"/><axis xyz="0 0 0"/></joint><gazebo reference="torso_base_link"><material>Gazebo/DarkGrey</material></gazebo><!-- Fixed column --><link name="torso_fixed_column_link"><visual><origin rpy="0 0 0" xyz="0 0 0.275"/><geometry><box size="0.18 0.2 0.55"/></geometry><material name="pal/DarkGrey"/></visual></link><joint name="torso_fixed_column_joint" type="fixed"><origin rpy="0 0 0" xyz="-0.028 0 0.205"/><parent link="base_link"/><child link="torso_fixed_column_link"/><axis xyz="0 0 0"/></joint><gazebo reference="torso_fixed_column_link"><material>Gazebo/DarkGrey</material></gazebo><!-- Lift torso --><link name="torso_lift_link"><inertial><origin rpy="0 0 0" xyz="0 0 0"/><mass value="3.24266045177967"/><inertia ixx="0.0295369723560087" ixy="-7.85101789883696E-07" ixz="-8.58576921315497E-05" iyy="0.0170989395656347" iyz="-8.17944373020342E-06" izz="0.0290055792681799"/></inertial><visual><origin rpy="0 0 0" xyz="0 0 0"/><geometry><mesh filename="package://tiago_pro_description/meshes/torso/torso_lift_link.stl"/></geometry><material name=""><color rgba="0.894117647058823 0.913725490196078 0.929411764705882 1"/></material></visual><collision><origin rpy="0 0 0" xyz="0 0 0"/><geometry><mesh filename="package://tiago_pro_description/meshes/torso/torso_lift_link_collision.stl"/></geometry></collision><collision><origin rpy="0 0 -1.5707963267949" xyz="-0.226436438571948 3.12797385809451E-05 0.00524038105676683"/><geometry><mesh filename="package://tiago_pro_description/meshes/torso/laptop_tray_collision.stl"/></geometry></collision></link><joint name="torso_lift_joint" type="prismatic"><origin rpy="0 0 0" xyz="0 0 0.5545"/><parent link="torso_base_link"/><child link="torso_lift_link"/><axis xyz="0 0 1"/><limit effort="2000" lower="0.0" upper="0.35" velocity="0.035"/><calibration rising="0.0"/><dynamics damping="1000"/><safety_controller k_position="20" k_velocity="20" soft_lower_limit="0.0" soft_upper_limit="0.35"/></joint><gazebo reference="torso_lift_joint"><implicitSpringDamper>1</implicitSpringDamper></gazebo><!-- Head mounting link --><link name="torso_head_link"><inertial><origin rpy="0 0 0" xyz="3.22658566531686E-16 -5.67885640993557E-18 -0.00811522365001816"/><mass value="0.19541960582329"/><inertia ixx="0.000439179732174765" ixy="5.76286393008048E-20" ixz="1.09094748941927E-18" iyy="0.000498456551929403" iyz="-1.60059406264224E-19" izz="0.000881920896131913"/></inertial><visual><origin rpy="0 0 0" xyz="0 0 0.01085"/><geometry><box size="0.11 0.092 0.0217"/></geometry><material name=""><color rgba="0.298039215686275 0.298039215686275 0.298039215686275 1"/></material></visual><collision><origin rpy="0 0 0" xyz="0 0 0.01085"/><geometry><box size="0.11 0.092 0.0217"/></geometry></collision></link><joint name="torso_head_joint" type="fixed"><origin rpy="0 0 0" xyz="0 0 0.0399999999999999"/><parent link="torso_lift_link"/><child link="torso_head_link"/><axis xyz="0 0 0"/></joint><!-- Torso arm left link--><link name="torso_arm_left_link"/><joint name="torso_arm_left_joint" type="fixed"><origin rpy="-2.06788770984932 0 -1.22173047639603" xyz="0.0898413194899453 0.159181203216899 -0.0920547375491735"/><parent link="torso_lift_link"/><child link="torso_arm_left_link"/><axis xyz="0 0 0"/></joint><!-- Torso arm right link --><link name="torso_arm_right_link"/><joint name="torso_arm_right_joint" type="fixed"><origin rpy="-2.06788770984932 0 -1.91986217719377" xyz="0.0898413194899453 -0.1591812032169 -0.0920547375491731"/><parent link="torso_lift_link"/><child link="torso_arm_right_link"/><axis xyz="0 0 0"/></joint><!-- Head Link 1--><link name="head_1_link"><inertial><origin rpy="0 0 0" xyz="-0.0037459 -4.6685E-05 0.1055"/><mass value="0.15566"/><inertia ixx="0.0005208" ixy="3.0453E-07" ixz="-6.1005E-05" iyy="0.00035021" iyz="5.8627E-07" izz="0.00033341"/></inertial><visual><origin rpy="0 0 0" xyz="0 0 0"/><geometry><mesh filename="package://tiago_pro_head_description/meshes/head_1_link.stl"/></geometry><material name=""><color rgba="0.29804 0.29804 0.29804 1"/></material></visual><collision><origin rpy="0 0 0" xyz="0 0 0"/><geometry><mesh filename="package://tiago_pro_head_description/meshes/head_1_link_collision.stl"/></geometry></collision></link><joint name="head_1_joint" type="revolute"><origin rpy="0 0 0" xyz="0 0 0"/><parent link="torso_head_link"/><child link="head_1_link"/><axis xyz="0 0 1"/><limit effort="5.197" lower="-1.309" upper="1.309" velocity="3.0"/><dynamics damping="0.5" friction="1.0"/><safety_controller k_position="20" k_velocity="20" soft_lower_limit="-1.2389999999999999" soft_upper_limit="1.2389999999999999"/></joint><!-- Head link 2--><link name="head_2_link"><inertial><origin rpy="0 0 0" xyz="0.01201 -0.10656 -0.00075"/><mass value="1.32153"/><inertia ixx="0.01065" ixy="-0.00119" ixz="0.00001" iyy="0.00878" iyz="-0.00003" izz="0.00627"/></inertial><visual><origin rpy="0 0 0" xyz="0 0 0"/><geometry><mesh filename="package://tiago_pro_head_description/meshes/realsense-d455_cover_link.stl"/></geometry><material name=""><color rgba="1 1 1 1"/></material></visual><visual><origin rpy="0 0 0" xyz="0 0 0"/><geometry><mesh filename="package://tiago_pro_head_description/meshes/head_2_link.stl"/></geometry><material name=""><color rgba="1 1 1 1"/></material></visual><collision><origin rpy="0 0 0" xyz="0 0 0"/><geometry><mesh filename="package://tiago_pro_head_description/meshes/head_2_link_collision.stl"/></geometry></collision></link><joint name="head_2_joint" type="revolute"><origin rpy="-1.5708 0 0" xyz="0.0425 0 0.10585"/><parent link="head_1_link"/><child link="head_2_link"/><axis xyz="0 0 -1"/><limit effort="2.77" lower="-1.0472" upper="0.34907" velocity="3.0"/><dynamics damping="0.5" friction="1.0"/><safety_controller k_position="20" k_velocity="20" soft_lower_limit="-0.9771999999999998" soft_upper_limit="0.27907"/></joint><link name="head_screen_link"><visual><origin rpy="1.5707963267948966 0 1.5707963267948966" xyz="0 0 0"/><geometry><box size="0.17282 0.10824 0.005"/></geometry><material name=""><color rgba="0 0 0 1"/></material></visual></link><gazebo reference="head_screen_link"><visual><plugin filename="libgazebo_ros_video.so" name="head_video_stream"><ros><!-- Add a namespace --><namespace/><!-- remap image subscribe topic --><remapping>~/image_raw:=robot_face/image_raw</remapping></ros><height>480</height><width>640</width></plugin></visual></gazebo><joint name="head_screen_joint" type="fixed"><parent link="head_2_link"/><child link="head_screen_link"/><origin rpy="1.5708 0 0" xyz="0.05584 -0.083935 0.0"/></joint><gazebo reference="head_1_link"><material>Gazebo/DarkGrey</material><mu1>0.9</mu1><mu2>0.9</mu2></gazebo><gazebo reference="head_2_link"><material>Gazebo/White</material><mu1>0.9</mu1><mu2>0.9</mu2></gazebo><gazebo reference="head_1_joint"><implicitSpringDamper>1</implicitSpringDamper></gazebo><gazebo reference="head_2_joint"><implicitSpringDamper>1</implicitSpringDamper></gazebo><!-- Cameras--><!-- camera body, with origin at bottom screw mount --><joint name="head_front_camera_joint" type="fixed"><origin rpy="1.5708 0 0" xyz="0.040453 -0.1565 0"/><parent link="head_2_link"/><child link="head_front_camera_bottom_screw_frame"/></joint><link name="head_front_camera_bottom_screw_frame"/><joint name="head_front_camera_link_joint" type="fixed"><origin rpy="0 0 0" xyz="0.011150000000000002 0.0475 0.0145"/><parent link="head_front_camera_bottom_screw_frame"/><child link="head_front_camera_link"/></joint><link name="head_front_camera_link"><visual><!-- the mesh origin is at front plate in between the two infrared camera axes --><!-- <origin xyz="${d455_zero_depth_to_glass-d455_cam_depth/2} ${-d455_cam_depth_py} 0" rpy="0 0 0"/> --><origin rpy="1.5707963267948966 0 1.5707963267948966" xyz="0.0046500000000000005 -0.0475 0"/><geometry><!-- <box size="${d455_cam_depth} ${d455_cam_width} ${d455_cam_height}"/> --><mesh filename="package://realsense2_description/meshes/d455.stl" scale="0.001 0.001 0.001"/></geometry><material name="aluminum"/></visual><collision><origin rpy="0 0 0" xyz="-0.00845 -0.0475 0"/><geometry><box size="0.026 0.124 0.029"/></geometry></collision><inertial><!-- The following are not reliable values, and should not be used for modeling --><mass value="0.072"/><origin xyz="0 0 0"/><inertia ixx="0.003881243" ixy="0.0" ixz="0.0" iyy="0.000498940" iyz="0.0" izz="0.003879257"/></inertial></link><gazebo reference="head_front_camera_link"><sensor name="head_front_camera" type="depth"><camera name="head_front_camera"><horizontal_fov>1.4870205226991688</horizontal_fov><vertical_fov>1.0122909661567112</vertical_fov><always_on>true</always_on><update_rate>30</update_rate><visualize>true</visualize><image><format>B8G8R8</format><width>848</width><height>480</height></image><clip><near>0.3</near><far>3.0</far></clip><noise><type>gaussian</type><mean>0.0</mean><stddev>0.100</stddev></noise></camera><plugin filename="libgazebo_ros_camera.so" name="head_front_camera"><frame_name>head_front_camera_depth_optical_frame</frame_name><min_depth>0.1</min_depth><max_depth>10.0</max_depth><ros><namespace></namespace><remapping>head_front_camera/image_raw:=head_front_camera/color/image_raw</remapping><remapping>head_front_camera/camera_info:=head_front_camera/color/camera_info</remapping><remapping>head_front_camera/image_raw/compressed:=head_front_camera/color/image_raw/compressed</remapping><remapping>head_front_camera/image_raw/compressedDepth:=head_front_camera/color/image_raw/compressedDepth</remapping><remapping>head_front_camera/image_raw/theora:=head_front_camera/color/image_raw/theora</remapping><remapping>head_front_camera/points:=head_front_camera/depth/color/points</remapping><remapping>head_front_camera/depth/image_raw:=head_front_camera/depth/image_rect_raw</remapping><remapping>head_front_camera/depth/image_raw/compressed:=head_front_camera/depth/image_rect_raw/compressed</remapping><remapping>head_front_camera/depth/image_raw/compressedDepth:=head_front_camera/depth/image_rect_raw/compressedDepth</remapping><remapping>head_front_camera/depth/image_raw/theora:=head_front_camera/depth/image_rect_raw/theora</remapping><qos><topic name="head_front_camera/color/image_raw"><publisher><reliability>best_effort</reliability><durability>volatile</durability><history depth="1">keep_last</history><liveliness>automatic</liveliness></publisher></topic><topic name="head_front_camera/color/camera_info"><publisher><reliability>best_effort</reliability><durability>volatile</durability><history depth="1">keep_last</history><liveliness>automatic</liveliness></publisher></topic><topic name="head_front_camera/color/image_raw/compressed"><publisher><reliability>best_effort</reliability><durability>volatile</durability><history depth="1">keep_last</history><liveliness>automatic</liveliness></publisher></topic><topic name="head_front_camera/color/image_raw/compressedDepth"><publisher><reliability>best_effort</reliability><durability>volatile</durability><history depth="1">keep_last</history><liveliness>automatic</liveliness></publisher></topic><topic name="head_front_camera/color/image_raw/theora"><publisher><reliability>best_effort</reliability><durability>volatile</durability><history depth="1">keep_last</history><liveliness>automatic</liveliness></publisher></topic><topic name="head_front_camera/depth/camera_info"><publisher><reliability>best_effort</reliability><durability>volatile</durability><history depth="1">keep_last</history><liveliness>automatic</liveliness></publisher></topic><topic name="head_front_camera/depth/color/points"><publisher><reliability>best_effort</reliability><durability>volatile</durability><history depth="1">keep_last</history><liveliness>automatic</liveliness></publisher></topic><topic name="head_front_camera/depth/image_rect_raw"><publisher><reliability>best_effort</reliability><durability>volatile</durability><history depth="1">keep_last</history><liveliness>automatic</liveliness></publisher></topic><topic name="head_front_camera/depth/image_rect_raw/compressed"><publisher><reliability>best_effort</reliability><durability>volatile</durability><history depth="1">keep_last</history><liveliness>automatic</liveliness></publisher></topic><topic name="head_front_camera/depth/image_rect_raw/compressedDepth"><publisher><reliability>best_effort</reliability><durability>volatile</durability><history depth="1">keep_last</history><liveliness>automatic</liveliness></publisher></topic><topic name="head_front_camera/depth/image_rect_raw/theora"><publisher><reliability>best_effort</reliability><durability>volatile</durability><history depth="1">keep_last</history><liveliness>automatic</liveliness></publisher></topic></qos></ros></plugin></sensor><!-- IMU Sensor --><sensor name="head_front_camera_imu_sensor" type="imu"><always_on>1</always_on><update_rate>200</update_rate><imu><noise><type>gaussian</type><rate><mean>0.0</mean><stddev>2e-4</stddev><bias_mean>0.0000075</bias_mean><bias_stddev>0.0000008</bias_stddev></rate><accel><mean>0.0</mean><stddev>1.7e-2</stddev><bias_mean>0.1</bias_mean><bias_stddev>0.001</bias_stddev></accel></noise></imu><plugin filename="libgazebo_ros_imu_sensor.so" name="head_front_camera_imu"><frame_name>head_front_camera_imu_optical_frame</frame_name><ros><namespace></namespace><!-- publish to /imu/data --><remapping>~/out:=head_front_camera/imu</remapping><qos><topic name="head_front_camera/imu"><publisher><reliability>best_effort</reliability><durability>volatile</durability><history depth="1">keep_last</history><liveliness>automatic</liveliness></publisher></topic></qos></ros></plugin></sensor></gazebo><!-- PROPERTIES --><!-- INCLUDES --><!-- ARM 1 LINK --><link name="arm_left_1_link"><inertial><origin rpy="0 0 0" xyz="0.0047632 0.015281 0.15179"/><mass value="1.2728"/><inertia ixx="0.0026718" ixy="2.956E-05" ixz="9.1714E-05" iyy="0.0024708" iyz="-0.00021103" izz="0.0010181"/></inertial><visual><origin rpy="0 0 0" xyz="0 0 0"/><geometry><mesh filename="package://pal_sea_arm_description/meshes/arm_tiago_pro/arm_1_link.stl" scale="1 1 1"/></geometry><material name="pal/DarkGrey"/></visual><collision><origin rpy="0 0 0" xyz="0 0 0"/><geometry><mesh filename="package://pal_sea_arm_description/meshes/arm_tiago_pro/arm_1_link_collision.stl" scale="1 1 1"/></geometry></collision></link><!-- ARM 1 JOINT --><joint name="arm_left_1_joint" type="revolute"><origin rpy="-2.0679 0.0 -1.2217" xyz="0.08976 0.15918 -0.092008"/><parent link="torso_lift_link"/><child link="arm_left_1_link"/><axis xyz="0 0 1"/><limit effort="43.0" lower="-0.5235987755982988" upper="4.71238898038469" velocity="1.95"/><safety_controller k_position="20" k_velocity="20" soft_lower_limit="-0.4535987755982988" soft_upper_limit="4.642388980384689"/><dynamics damping="1.0" friction="1.0"/></joint><!-- ARM 2 LINK --><link name="arm_left_2_link"><inertial><origin rpy="0 0 0" xyz="0.016761 -0.11092 -0.029509"/><mass value="1.0974"/><inertia ixx="0.0017447" ixy="0.00015165" ixz="1.4253E-05" iyy="0.00092895" iyz="-0.00017788" izz="0.0018861"/></inertial><visual><origin rpy="0 0 0" xyz="0 0 0"/><geometry><mesh filename="package://pal_sea_arm_description/meshes/arm_tiago_pro/arm_2_link.stl" scale="1 1 1"/></geometry><material name="pal/DarkGrey"/></visual><collision><origin rpy="0 0 0" xyz="0 0 0"/><geometry><mesh filename="package://pal_sea_arm_description/meshes/arm_tiago_pro/arm_2_link_collision.stl" scale="1 1 1"/></geometry></collision></link><!-- ARM 2 JOINT --><joint name="arm_left_2_joint" type="revolute"><origin rpy="-1.57079632679489 0 -1.5707963267949" xyz="0.0371099999999995 0.02 0.18"/><parent link="arm_left_1_link"/><child link="arm_left_2_link"/><axis xyz="0 0 1"/><limit effort="43.0" lower="-2.443460952792061" upper="1.1344640137963142" velocity="1.95"/><dynamics damping="1.0" friction="1.0"/><safety_controller k_position="20" k_velocity="20" soft_lower_limit="-2.3734609527920614" soft_upper_limit="1.0644640137963142"/></joint><!-- ARM 3 LINK --><link name="arm_left_3_link"><inertial><origin rpy="0 0 0" xyz="0.014943 -0.0047866 0.12972"/><mass value="1.1907"/><inertia ixx="0.0024631" ixy="-2.9584E-05" ixz="-0.00021101" iyy="0.0026656" iyz="-9.1746E-05" izz="0.0010104"/></inertial><visual><origin rpy="0 0 0" xyz="0 0 0"/><geometry><mesh filename="package://pal_sea_arm_description/meshes/arm_tiago_pro/arm_3_link.stl" scale="1 1 1"/></geometry><material name="pal/DarkGrey"/></visual><collision><origin rpy="0 0 0" xyz="0 0 0"/><geometry><mesh filename="package://pal_sea_arm_description/meshes/arm_tiago_pro/arm_3_link_collision.stl" scale="1 1 1"/></geometry></collision></link><!-- ARM 3 JOINT --><joint name="arm_left_3_joint" type="revolute"><origin rpy="1.5707963267949 0 0" xyz="0.019999999999999 -0.17011 -0.037110000000001"/><parent link="arm_left_2_link"/><child link="arm_left_3_link"/><axis xyz="0 0 1"/><limit effort="26" lower="-2.6179938779914944" upper="2.6179938779914944" velocity="3.95"/><safety_controller k_position="20" k_velocity="20" soft_lower_limit="-2.5479938779914946" soft_upper_limit="2.5479938779914946"/><dynamics damping="1.0" friction="1.0"/></joint><!-- ARM 4 LINK --><link name="arm_left_4_link"><inertial><origin rpy="0 0 0" xyz="-0.016761 0.11092 -0.029509"/><mass value="1.0974"/><inertia ixx="0.0017447" ixy="0.00015165" ixz="-1.4253E-05" iyy="0.00092895" iyz="0.00017788" izz="0.0018861"/></inertial><visual><origin rpy="0 0 0" xyz="0 0 0"/><geometry><mesh filename="package://pal_sea_arm_description/meshes/arm_tiago_pro/arm_4_link.stl" scale="1 1 1"/></geometry><material name="pal/DarkGrey"/></visual><collision><origin rpy="0 0 0" xyz="0 0 0"/><geometry><mesh filename="package://pal_sea_arm_description/meshes/arm_tiago_pro/arm_4_link_collision.stl" scale="1 1 1"/></geometry></collision></link><!-- ARM 4 JOINT --><joint name="arm_left_4_joint" type="revolute"><origin rpy="1.57079632679489 0 0" xyz="0.0199999999999993 -0.0371100000000008 0.15989"/><parent link="arm_left_3_link"/><child link="arm_left_4_link"/><axis xyz="0 0 1"/><limit effort="26" lower="-2.443460952792061" upper="1.1344640137963142" velocity="3.95"/><dynamics damping="1.0" friction="1.0"/><safety_controller k_position="20" k_velocity="20" soft_lower_limit="-2.3734609527920614" soft_upper_limit="1.0644640137963142"/></joint><!-- ARM 5 LINK --><link name="arm_left_5_link"><inertial><origin rpy="0 0 0" xyz="-6.6854E-07 -0.02662 0.067326"/><mass value="0.34802"/><inertia ixx="0.0014602" ixy="-1.4931E-08" ixz="8.1828E-08" iyy="0.0014558" iyz="0.00033448" izz="0.00040968"/></inertial><visual><origin rpy="0 0 0" xyz="0 0 0"/><geometry><mesh filename="package://pal_sea_arm_description/meshes/arm_tiago_pro/spherical-wrist/arm_5_link.stl" scale="1 1 1"/></geometry><material name="pal/DarkGrey"/></visual><collision><origin rpy="0 0 0" xyz="0 0 0"/><geometry><mesh filename="package://pal_sea_arm_description/meshes/arm_tiago_pro/spherical-wrist/arm_5_link_collision.stl" scale="1 1 1"/></geometry></collision></link><!-- ARM 5 JOINT --><joint name="arm_left_5_joint" type="revolute"><!-- Check new limits --><origin rpy="-1.5707963267949 3.14 0" xyz="-0.0199999999999971 0.17011 -0.037110000000002"/><parent link="arm_left_4_link"/><child link="arm_left_5_link"/><axis xyz="0 0 1"/><limit effort="26" lower="-3.6651914291880923" upper="1.5707963267948966" velocity="3.95"/><safety_controller k_position="20" k_velocity="20" soft_lower_limit="-3.5951914291880924" soft_upper_limit="1.5007963267948965"/><dynamics damping="1.0" friction="1.0"/></joint><!-- ARM 6 LINK --><link name="arm_left_6_link"><inertial><origin rpy="0 0 0" xyz="0.031968 -0.0065097 -0.040676"/><mass value="1.378"/><inertia ixx="0.0011002" ixy="0.00012805" ixz="-5.6797E-06" iyy="0.0011658" iyz="5.4596E-07" izz="0.0011909"/></inertial><visual><origin rpy="0 0 0" xyz="0 0 0"/><geometry><mesh filename="package://pal_sea_arm_description/meshes/arm_tiago_pro/spherical-wrist/arm_6_link.stl" scale="1 1 1"/></geometry><material name="pal/DarkGrey"/></visual><collision><origin rpy="0 0 0" xyz="0 0 0"/><geometry><mesh filename="package://pal_sea_arm_description/meshes/arm_tiago_pro/spherical-wrist/arm_6_link_collision.stl" scale="1 1 1"/></geometry></collision></link><!-- ARM 6 JOINT --><joint name="arm_left_6_joint" type="revolute"><origin rpy="-1.5708 0 3.14" xyz="0 -0.0422 0.1654"/><parent link="arm_left_5_link"/><child link="arm_left_6_link"/><axis xyz="0 0 -1"/><limit effort="26" lower="-1.8849555921538759" upper="3.001966313430247" velocity="3.95"/><dynamics damping="1.0" friction="1.0"/><safety_controller k_position="20" k_velocity="20" soft_lower_limit="-1.8149555921538758" soft_upper_limit="2.931966313430247"/></joint><!-- ARM 7 LINK --><link name="arm_left_7_link"><inertial><origin rpy="0 0 0" xyz="-0.0016034 0.001194 0.0075583"/><mass value="0.1354"/><inertia ixx="5.0537E-05" ixy="-8.1184E-07" ixz="1.9023E-07" iyy="5.1762E-05" iyz="-3.2751E-07" izz="9.5274E-05"/></inertial><visual><origin rpy="0 0 0" xyz="0 0 0"/><geometry><mesh filename="package://pal_sea_arm_description/meshes/arm_tiago_pro/spherical-wrist/arm_7_link.stl" scale="1 1 1"/></geometry><material name="pal/DarkGrey"/></visual><collision><origin rpy="0 0 0" xyz="0 0 0"/><geometry><mesh filename="package://pal_sea_arm_description/meshes/arm_tiago_pro/spherical-wrist/arm_7_link_collision.stl" scale="1 1 1"/></geometry></collision></link><!-- ARM 7 JOINT --><joint name="arm_left_7_joint" type="revolute"><origin rpy="1.5708 0 0" xyz="0.07 -0.0534 -0.0422"/><parent link="arm_left_6_link"/><child link="arm_left_7_link"/><axis xyz="0 0 1"/><limit effort="26" lower="-2.6179938779914944" upper="2.6179938779914944" velocity="3.95"/><dynamics damping="1.0" friction="1.0"/><safety_controller k_position="20" k_velocity="20" soft_lower_limit="-2.5479938779914946" soft_upper_limit="2.5479938779914946"/></joint><!--***********************--><!--        TOOL           --><!--***********************--><link name="arm_left_tool_link"/><joint name="arm_left_tool_joint" type="fixed"><parent link="arm_left_7_link"/><child link="arm_left_tool_link"/><origin rpy="0 0 0" xyz="0 0 0.017"/></joint><!-- GAZEBO PROPERTIES --><gazebo reference="arm_left_1_link"><material>Gazebo/DarkGrey</material><mu1>0.9</mu1><mu2>0.9</mu2></gazebo><gazebo reference="arm_left_1_joint"><implicitSpringDamper>1</implicitSpringDamper></gazebo><gazebo reference="arm_left_2_link"><material>Gazebo/DarkGrey</material><mu1>0.9</mu1><mu2>0.9</mu2></gazebo><gazebo reference="arm_left_2_joint"><implicitSpringDamper>1</implicitSpringDamper></gazebo><gazebo reference="arm_left_3_link"><material>Gazebo/DarkGrey</material><mu1>0.9</mu1><mu2>0.9</mu2></gazebo><gazebo reference="arm_left_3_joint"><implicitSpringDamper>1</implicitSpringDamper></gazebo><gazebo reference="arm_left_4_link"><material>Gazebo/DarkGrey</material><mu1>0.9</mu1><mu2>0.9</mu2></gazebo><gazebo reference="arm_left_4_joint"><implicitSpringDamper>1</implicitSpringDamper></gazebo><gazebo reference="arm_left_5_link"><material>Gazebo/DarkGrey</material><mu1>0.9</mu1><mu2>0.9</mu2></gazebo><gazebo reference="arm_left_5_joint"><implicitSpringDamper>1</implicitSpringDamper></gazebo><gazebo reference="arm_left_6_link"><material>Gazebo/DarkGrey</material><mu1>0.9</mu1><mu2>0.9</mu2></gazebo><gazebo reference="arm_left_6_joint"><implicitSpringDamper>1</implicitSpringDamper></gazebo><gazebo reference="arm_left_7_link"><material>Gazebo/DarkGrey</material><mu1>0.9</mu1><mu2>0.9</mu2></gazebo><gazebo reference="arm_left_7_joint"><implicitSpringDamper>1</implicitSpringDamper><provideFeedback>1</provideFeedback></gazebo><gazebo reference="arm_left_tool_link"><material>Gazebo/DarkGrey</material><mu1>0.9</mu1><mu2>0.9</mu2></gazebo><!-- GRIPPER DEFINITION --><!-- Base link --><link name="gripper_left_base_link"><inertial><origin rpy="0 0 0" xyz="-5.081E-05 6.06E-06 0.04330857"/><mass value="0.59671873"/><inertia ixx="0.00064209" ixy="-2.1E-07" ixz="6.5E-07" iyy="0.00060742" iyz="2.1E-07" izz="0.00037836"/></inertial><visual><origin rpy="0 0 0" xyz="0 0 0"/><geometry><mesh filename="package://pal_pro_gripper_description/meshes/base_link_tc.stl"/></geometry><material name="pal/DarkGrey"/></visual><collision><origin rpy="0 0 0" xyz="0 0 0"/><geometry><mesh filename="package://pal_pro_gripper_description/meshes/base_link_tc.stl"/></geometry></collision></link><joint name="gripper_left_base_joint" type="fixed"><origin rpy="0 0 0" xyz="0.0 0.0 0.0"/><parent link="arm_left_tool_link"/><child link="gripper_left_base_link"/><axis xyz="0 0 0"/></joint><gazebo reference="gripper_left_grasping_link"><material>Gazebo/Blue</material><turnGravityOff>true</turnGravityOff></gazebo><joint name="gripper_left_grasping_frame_joint" type="fixed"><parent link="gripper_left_base_link"/><child link="gripper_left_grasping_link"/><origin rpy="0 -1.57 0" xyz="0.0 0.0 0.157157"/></joint><link name="gripper_left_grasping_link"><inertial><mass value="1e-9"/><inertia ixx="1e-9" ixy="0.0" ixz="0.0" iyy="1e-9" iyz="0.0" izz="1e-9"/></inertial></link><!-- Screw link --><link name="gripper_left_screw_left_link"><inertial><origin rpy="0 0 0" xyz="0.0 0.0 0.0"/><mass value="0.02"/><inertia ixx="7.4666667e-07" ixy="0.0" ixz="0.0" iyy="7.4666667e-07" iyz="0.0" izz="1.6e-07"/></inertial></link><joint name="gripper_left_finger_joint" type="prismatic"><origin rpy="0 0 0" xyz="-0.0178 0.0088 0.0"/><parent link="gripper_left_base_finger_left_link"/><child link="gripper_left_screw_left_link"/><axis xyz="0 1 0"/><limit effort="10.0" lower="0.0" upper="0.07" velocity="2"/><safety_controller k_position="20" k_velocity="20" soft_lower_limit="0.0" soft_upper_limit="0.07"/><dynamics damping="0.03"/></joint><!-- Gripper base finger link--><link name="gripper_left_base_finger_left_link"><inertial><origin rpy="0 0 0" xyz="0.0 0.0 0.0"/><mass value="0.02"/><inertia ixx="7.4666667e-07" ixy="0.0" ixz="0.0" iyy="7.4666667e-07" iyz="0.0" izz="1.6e-07"/></inertial><visual><origin rpy="0 0 0" xyz="0 0 0"/><geometry><sphere radius="0.001"/></geometry><material name=""><color rgba="0.752941176470588 0.752941176470588 0.752941176470588 1"/></material></visual><collision><origin rpy="0 0 0" xyz="0 0 0"/><geometry><sphere radius="0.001"/></geometry></collision></link><joint name="gripper_left_base_finger_left_joint" type="fixed"><origin rpy="1.5708 0 -1.5708" xyz="0.0 -0.0288 0.07565"/><parent link="gripper_left_base_link"/><child link="gripper_left_base_finger_left_link"/></joint><!-- Inner finger --><link name="gripper_left_inner_finger_left_link"><inertial><origin rpy="0 0 0" xyz="-1.7347E-18 0.024759 0"/><mass value="0.018619"/><inertia ixx="4.8806E-06" ixy="-7.6762E-22" ixz="1.0244E-22" iyy="2.5471E-07" iyz="-1.1841E-21" izz="4.9573E-06"/></inertial><visual><origin rpy="0 0 0" xyz="0 0 0"/><geometry><mesh filename="package://pal_pro_gripper_description/meshes/inner_finger.stl"/></geometry><material name=""><color rgba="0.752941176470588 0.752941176470588 0.752941176470588 1"/></material></visual><collision><origin rpy="0 0 0" xyz="0 0 0"/><geometry><mesh filename="package://pal_pro_gripper_description/meshes/inner_finger.stl"/></geometry></collision></link><joint name="gripper_left_inner_finger_left_joint" type="revolute"><origin rpy="0.0 0.0 0.0" xyz="-0.01482273272 0.00453176142 0.0"/><parent link="gripper_left_base_finger_left_link"/><child link="gripper_left_inner_finger_left_link"/><axis xyz="0 0 1"/><limit effort="0.1" lower="-0.7476990515543709" upper="0.1396437934520663" velocity="2"/><mimic joint="gripper_left_finger_joint" multiplier="-8.28" offset="0.0"/></joint><!-- Outer finger --><link name="gripper_left_outer_finger_left_link"><inertial><origin rpy="0 0 0" xyz="-0.00128298420356912 0.0143974756929021 1.5011142385525E-15"/><mass value="0.0159887772377711"/><inertia ixx="5.98786243781872E-06" ixy="-5.21728921919786E-07" ixz="-7.65398863989897E-20" iyy="4.87250835241547E-07" iyz="-7.03393901384231E-19" izz="6.14972693188202E-06"/></inertial><visual><origin rpy="0 0 0" xyz="0 0 0"/><geometry><mesh filename="package://pal_pro_gripper_description/meshes/outer_finger.stl"/></geometry><material name=""><color rgba="0.752941176470588 0.752941176470588 0.752941176470588 1"/></material></visual><collision><origin rpy="0 0 0" xyz="0 0 0"/><geometry><mesh filename="package://pal_pro_gripper_description/meshes/outer_finger.stl"/></geometry></collision></link><joint name="gripper_left_outer_finger_left_joint" type="revolute"><origin rpy="1.5708 0 -1.5708" xyz="0.0 -0.0288 0.07565"/><parent link="gripper_left_base_link"/><child link="gripper_left_outer_finger_left_link"/><axis xyz="0 0 1"/><limit effort="0.1" lower="-0.7476990515543709" upper="0.1396437934520663" velocity="2"/><mimic joint="gripper_left_finger_joint" multiplier="-8.28" offset="0.0"/></joint><!-- Fingertip --><link name="gripper_left_fingertip_left_link"><inertial><origin rpy="0 0 0" xyz="-0.000864586242839444 0.0119290372347422 -2.732444563276E-11"/><mass value="0.0335029606041878"/><inertia ixx="3.6391786422032E-06" ixy="3.4052204633865E-07" ixz="-1.41918626749374E-14" iyy="1.70950026855986E-06" iyz="-4.24736685249643E-14" izz="2.84428135741107E-06"/></inertial><visual><origin rpy="0 0 0" xyz="0 0 0"/><geometry><mesh filename="package://pal_pro_gripper_description/meshes/fingertip.stl"/></geometry><material name=""><color rgba="0.752941176470588 0.752941176470588 0.752941176470588 1"/></material></visual><collision><origin rpy="0 0 0" xyz="0 0 0"/><geometry><mesh filename="package://pal_pro_gripper_description/meshes/fingertip.stl"/></geometry></collision></link><joint name="gripper_left_fingertip_left_joint" type="revolute"><origin rpy="0 0 0" xyz="0 0.05 0"/><parent link="gripper_left_inner_finger_left_link"/><child link="gripper_left_fingertip_left_link"/><axis xyz="0 0 1"/><limit effort="0.1" lower="-0.1396437934520663" upper="0.7476990515543709" velocity="2"/><mimic joint="gripper_left_finger_joint" multiplier="8.28" offset="0.0"/></joint><!-- Screw link --><link name="gripper_left_screw_right_link"><inertial><origin rpy="0 0 0" xyz="0.0 0.0 0.0"/><mass value="0.02"/><inertia ixx="7.4666667e-07" ixy="0.0" ixz="0.0" iyy="7.4666667e-07" iyz="0.0" izz="1.6e-07"/></inertial></link><joint name="gripper_left_finger_right_joint" type="prismatic"><origin rpy="0 0 0" xyz="-0.0178 0.0088 0.0"/><parent link="gripper_left_base_finger_right_link"/><child link="gripper_left_screw_right_link"/><axis xyz="0 1 0"/><limit effort="10.0" lower="0.0" upper="0.07" velocity="2"/><safety_controller k_position="20" k_velocity="20" soft_lower_limit="0.0" soft_upper_limit="0.07"/><mimic joint="gripper_left_finger_joint" multiplier="0.22" offset="0"/></joint><!-- Gripper base finger link--><link name="gripper_left_base_finger_right_link"><inertial><origin rpy="0 0 0" xyz="0.0 0.0 0.0"/><mass value="0.02"/><inertia ixx="7.4666667e-07" ixy="0.0" ixz="0.0" iyy="7.4666667e-07" iyz="0.0" izz="1.6e-07"/></inertial><visual><origin rpy="0 0 0" xyz="0 0 0"/><geometry><sphere radius="0.001"/></geometry><material name=""><color rgba="0.752941176470588 0.752941176470588 0.752941176470588 1"/></material></visual><collision><origin rpy="0 0 0" xyz="0 0 0"/><geometry><sphere radius="0.001"/></geometry></collision></link><joint name="gripper_left_base_finger_right_joint" type="fixed"><origin rpy="1.5708 0 1.5708" xyz="0.0 0.0288 0.07565"/><parent link="gripper_left_base_link"/><child link="gripper_left_base_finger_right_link"/></joint><!-- Inner finger --><link name="gripper_left_inner_finger_right_link"><inertial><origin rpy="0 0 0" xyz="-1.7347E-18 0.024759 0"/><mass value="0.018619"/><inertia ixx="4.8806E-06" ixy="-7.6762E-22" ixz="1.0244E-22" iyy="2.5471E-07" iyz="-1.1841E-21" izz="4.9573E-06"/></inertial><visual><origin rpy="0 0 0" xyz="0 0 0"/><geometry><mesh filename="package://pal_pro_gripper_description/meshes/inner_finger.stl"/></geometry><material name=""><color rgba="0.752941176470588 0.752941176470588 0.752941176470588 1"/></material></visual><collision><origin rpy="0 0 0" xyz="0 0 0"/><geometry><mesh filename="package://pal_pro_gripper_description/meshes/inner_finger.stl"/></geometry></collision></link><joint name="gripper_left_inner_finger_right_joint" type="revolute"><origin rpy="0.0 0.0 0.0" xyz="-0.01482273272 0.00453176142 0.0"/><parent link="gripper_left_base_finger_right_link"/><child link="gripper_left_inner_finger_right_link"/><axis xyz="0 0 1"/><limit effort="0.1" lower="-0.7476990515543709" upper="0.1396437934520663" velocity="2"/><mimic joint="gripper_left_finger_joint" multiplier="-8.28" offset="0.0"/></joint><!-- Outer finger --><link name="gripper_left_outer_finger_right_link"><inertial><origin rpy="0 0 0" xyz="-0.00128298420356912 0.0143974756929021 1.5011142385525E-15"/><mass value="0.0159887772377711"/><inertia ixx="5.98786243781872E-06" ixy="-5.21728921919786E-07" ixz="-7.65398863989897E-20" iyy="4.87250835241547E-07" iyz="-7.03393901384231E-19" izz="6.14972693188202E-06"/></inertial><visual><origin rpy="0 0 0" xyz="0 0 0"/><geometry><mesh filename="package://pal_pro_gripper_description/meshes/outer_finger.stl"/></geometry><material name=""><color rgba="0.752941176470588 0.752941176470588 0.752941176470588 1"/></material></visual><collision><origin rpy="0 0 0" xyz="0 0 0"/><geometry><mesh filename="package://pal_pro_gripper_description/meshes/outer_finger.stl"/></geometry></collision></link><joint name="gripper_left_outer_finger_right_joint" type="revolute"><origin rpy="1.5708 0 1.5708" xyz="0.0 0.0288 0.07565"/><parent link="gripper_left_base_link"/><child link="gripper_left_outer_finger_right_link"/><axis xyz="0 0 1"/><limit effort="0.1" lower="-0.7476990515543709" upper="0.1396437934520663" velocity="2"/><mimic joint="gripper_left_finger_joint" multiplier="-8.28" offset="0.0"/></joint><!-- Fingertip --><link name="gripper_left_fingertip_right_link"><inertial><origin rpy="0 0 0" xyz="-0.000864586242839444 0.0119290372347422 -2.732444563276E-11"/><mass value="0.0335029606041878"/><inertia ixx="3.6391786422032E-06" ixy="3.4052204633865E-07" ixz="-1.41918626749374E-14" iyy="1.70950026855986E-06" iyz="-4.24736685249643E-14" izz="2.84428135741107E-06"/></inertial><visual><origin rpy="0 0 0" xyz="0 0 0"/><geometry><mesh filename="package://pal_pro_gripper_description/meshes/fingertip.stl"/></geometry><material name=""><color rgba="0.752941176470588 0.752941176470588 0.752941176470588 1"/></material></visual><collision><origin rpy="0 0 0" xyz="0 0 0"/><geometry><mesh filename="package://pal_pro_gripper_description/meshes/fingertip.stl"/></geometry></collision></link><joint name="gripper_left_fingertip_right_joint" type="revolute"><origin rpy="0 0 0" xyz="0 0.05 0"/><parent link="gripper_left_inner_finger_right_link"/><child link="gripper_left_fingertip_right_link"/><axis xyz="0 0 1"/><limit effort="0.1" lower="-0.1396437934520663" upper="0.7476990515543709" velocity="2"/><mimic joint="gripper_left_finger_joint" multiplier="8.28" offset="0.0"/></joint><!-- Gazebo config --><gazebo reference="gripper_left_inner_finger_left_link"><material>Gazebo/White</material><mu1>0.9</mu1><mu2>0.9</mu2></gazebo><gazebo reference="gripper_left_inner_finger_right_link"><material>Gazebo/White</material><mu1>0.9</mu1><mu2>0.9</mu2></gazebo><gazebo reference="gripper_left_outer_finger_left_link"><material>Gazebo/White</material><mu1>0.9</mu1><mu2>0.9</mu2></gazebo><gazebo reference="gripper_left_outer_finger_right_link"><material>Gazebo/White</material><mu1>0.9</mu1><mu2>0.9</mu2></gazebo><gazebo reference="gripper_left_fingertip_right_link"><material>Gazebo/White</material><mu1>0.9</mu1><mu2>0.9</mu2></gazebo><gazebo reference="gripper_left_fingertip_left_link"><material>Gazebo/White</material><mu1>0.9</mu1><mu2>0.9</mu2></gazebo><gazebo reference="gripper_left_base_link"><material>Gazebo/DarkGrey</material><mu1>0.9</mu1><mu2>0.9</mu2></gazebo><!-- Screw links --><gazebo reference="gripper_left_finger_joint"><material>Gazebo/DarkGrey</material><mu1>0.9</mu1><mu2>0.9</mu2></gazebo><gazebo reference="gripper_left_finger_joint"><material>Gazebo/DarkGrey</material><mu1>0.9</mu1><mu2>0.9</mu2></gazebo><!-- Base finger links --><gazebo reference="gripper_left_base_finger_left_link"><material>Gazebo/DarkGrey</material><mu1>0.9</mu1><mu2>0.9</mu2></gazebo><gazebo reference="gripper_left_base_finger_right_link"><material>Gazebo/DarkGrey</material><mu1>0.9</mu1><mu2>0.9</mu2></gazebo><gazebo><plugin filename="libgazebo_ros_mimic_joint.so" name="mimic_joint_plugin_right"><joint>gripper_finger_joint</joint><mimicJoint>gripper_finger_right_joint</mimicJoint><multiplier>1.0</multiplier><offset>0.0</offset></plugin></gazebo><!-- Base finger links --><gazebo reference="gripper_left_base_finger_left_link"><material>Gazebo/DarkGrey</material><mu1>0.9</mu1><mu2>0.9</mu2></gazebo><gazebo reference="gripper_left_base_finger_right_link"><material>Gazebo/DarkGrey</material><mu1>0.9</mu1><mu2>0.9</mu2></gazebo><!-- PAL Pro Prototype --><!-- <xacro:if value="${type == 'pal-pro-gripper-prototype'}">
      <xacro:include filename="$(find pal_pro_gripper_description)/urdf/pro_gripper_prototype.urdf.xacro" />
      <xacro:pal_pro_gripper_prototype name="${name}" parent="${parent}">
        <origin xyz="0.052 0.0 0.0" rpy="0 ${90 * deg_to_rad} 0"/>
      </xacro:pal_pro_gripper_prototype>
    </xacro:if> --><!-- Custom --><!-- <xacro:if value="${type == 'custom' and not is_dual}">
    <xacro:include filename="$(find custom_ee_description)/urdf/end-effector.urdf.xacro" />
    <xacro:end_effector parent="${parent}">
      <origin xyz="0.0 0 0" rpy="0 0 0"/>
    </xacro:end_effector>
  </xacro:if> --><!-- Custom dual--><!-- <xacro:if value="${type == 'custom' and is_dual}"> --><!-- If right --><!-- <xacro:if value="${reflect == 1}">
    <xacro:include filename="$(find custom_dual_ee_description)/urdf/end-effector-right.urdf.xacro" />
    <xacro:end_effector_right parent="${parent}">
      <origin xyz="0.0 0 0" rpy="0 0 0"/>
    </xacro:end_effector_right>
    </xacro:if> --><!-- If left --><!-- <xacro:if value="${reflect == -1}">
    <xacro:include filename="$(find custom_dual_ee_description)/urdf/end-effector-left.urdf.xacro" />
    <xacro:end_effector_left parent="${parent}">
      <origin xyz="0.0 0 0" rpy="0 0 0"/>
    </xacro:end_effector_left>
    </xacro:if>
  </xacro:if> --><!-- PROPERTIES --><!-- INCLUDES --><!-- ARM 1 LINK --><link name="arm_right_1_link"><inertial><origin rpy="0 0 0" xyz="0.0047632 0.015281 0.15179"/><mass value="1.2728"/><inertia ixx="0.0026718" ixy="2.956E-05" ixz="9.1714E-05" iyy="0.0024708" iyz="-0.00021103" izz="0.0010181"/></inertial><visual><origin rpy="0 0 0" xyz="0 0 0"/><geometry><mesh filename="package://pal_sea_arm_description/meshes/arm_tiago_pro/arm_1_link.stl" scale="1 1 1"/></geometry><material name="pal/DarkGrey"/></visual><collision><origin rpy="0 0 0" xyz="0 0 0"/><geometry><mesh filename="package://pal_sea_arm_description/meshes/arm_tiago_pro/arm_1_link_collision.stl" scale="1 1 1"/></geometry></collision></link><!-- ARM 1 JOINT --><joint name="arm_right_1_joint" type="revolute"><origin rpy="-2.0679 -0.0 -1.9198899999999999" xyz="0.08976 -0.15918 -0.092008"/><parent link="torso_lift_link"/><child link="arm_right_1_link"/><axis xyz="0 0 1"/><limit effort="43.0" lower="-4.71238898038469" upper="0.5235987755982988" velocity="1.95"/><safety_controller k_position="20" k_velocity="20" soft_lower_limit="-4.642388980384689" soft_upper_limit="0.4535987755982988"/><dynamics damping="1.0" friction="1.0"/></joint><!-- ARM 2 LINK --><link name="arm_right_2_link"><inertial><origin rpy="0 0 0" xyz="0.016761 -0.11092 -0.029509"/><mass value="1.0974"/><inertia ixx="0.0017447" ixy="0.00015165" ixz="1.4253E-05" iyy="0.00092895" iyz="-0.00017788" izz="0.0018861"/></inertial><visual><origin rpy="0 0 0" xyz="0 0 0"/><geometry><mesh filename="package://pal_sea_arm_description/meshes/arm_tiago_pro/arm_2_link.stl" scale="1 1 1"/></geometry><material name="pal/DarkGrey"/></visual><collision><origin rpy="0 0 0" xyz="0 0 0"/><geometry><mesh filename="package://pal_sea_arm_description/meshes/arm_tiago_pro/arm_2_link_collision.stl" scale="1 1 1"/></geometry></collision></link><!-- ARM 2 JOINT --><joint name="arm_right_2_joint" type="revolute"><origin rpy="-1.57079632679489 0 -1.5707963267949" xyz="0.0371099999999995 0.02 0.18"/><parent link="arm_right_1_link"/><child link="arm_right_2_link"/><axis xyz="0 0 1"/><limit effort="43.0" lower="-2.443460952792061" upper="1.1344640137963142" velocity="1.95"/><dynamics damping="1.0" friction="1.0"/><safety_controller k_position="20" k_velocity="20" soft_lower_limit="-2.3734609527920614" soft_upper_limit="1.0644640137963142"/></joint><!-- ARM 3 LINK --><link name="arm_right_3_link"><inertial><origin rpy="0 0 0" xyz="0.014943 -0.0047866 0.12972"/><mass value="1.1907"/><inertia ixx="0.0024631" ixy="-2.9584E-05" ixz="-0.00021101" iyy="0.0026656" iyz="-9.1746E-05" izz="0.0010104"/></inertial><visual><origin rpy="0 0 0" xyz="0 0 0"/><geometry><mesh filename="package://pal_sea_arm_description/meshes/arm_tiago_pro/arm_3_link.stl" scale="1 1 1"/></geometry><material name="pal/DarkGrey"/></visual><collision><origin rpy="0 0 0" xyz="0 0 0"/><geometry><mesh filename="package://pal_sea_arm_description/meshes/arm_tiago_pro/arm_3_link_collision.stl" scale="1 1 1"/></geometry></collision></link><!-- ARM 3 JOINT --><joint name="arm_right_3_joint" type="revolute"><origin rpy="1.5707963267949 0 0" xyz="0.019999999999999 -0.17011 -0.037110000000001"/><parent link="arm_right_2_link"/><child link="arm_right_3_link"/><axis xyz="0 0 1"/><limit effort="26" lower="-2.6179938779914944" upper="2.6179938779914944" velocity="3.95"/><safety_controller k_position="20" k_velocity="20" soft_lower_limit="-2.5479938779914946" soft_upper_limit="2.5479938779914946"/><dynamics damping="1.0" friction="1.0"/></joint><!-- ARM 4 LINK --><link name="arm_right_4_link"><inertial><origin rpy="0 0 0" xyz="-0.016761 0.11092 -0.029509"/><mass value="1.0974"/><inertia ixx="0.0017447" ixy="0.00015165" ixz="-1.4253E-05" iyy="0.00092895" iyz="0.00017788" izz="0.0018861"/></inertial><visual><origin rpy="0 0 0" xyz="0 0 0"/><geometry><mesh filename="package://pal_sea_arm_description/meshes/arm_tiago_pro/arm_4_link.stl" scale="1 1 1"/></geometry><material name="pal/DarkGrey"/></visual><collision><origin rpy="0 0 0" xyz="0 0 0"/><geometry><mesh filename="package://pal_sea_arm_description/meshes/arm_tiago_pro/arm_4_link_collision.stl" scale="1 1 1"/></geometry></collision></link><!-- ARM 4 JOINT --><joint name="arm_right_4_joint" type="revolute"><origin rpy="1.57079632679489 0 0" xyz="0.0199999999999993 -0.0371100000000008 0.15989"/><parent link="arm_right_3_link"/><child link="arm_right_4_link"/><axis xyz="0 0 1"/><limit effort="26" lower="-2.443460952792061" upper="1.1344640137963142" velocity="3.95"/><dynamics damping="1.0" friction="1.0"/><safety_controller k_position="20" k_velocity="20" soft_lower_limit="-2.3734609527920614" soft_upper_limit="1.0644640137963142"/></joint><!-- ARM 5 LINK --><link name="arm_right_5_link"><inertial><origin rpy="0 0 0" xyz="-6.6854E-07 -0.02662 0.067326"/><mass value="0.34802"/><inertia ixx="0.0014602" ixy="-1.4931E-08" ixz="8.1828E-08" iyy="0.0014558" iyz="0.00033448" izz="0.00040968"/></inertial><visual><origin rpy="0 0 0" xyz="0 0 0"/><geometry><mesh filename="package://pal_sea_arm_description/meshes/arm_tiago_pro/spherical-wrist/arm_5_link.stl" scale="1 1 1"/></geometry><material name="pal/DarkGrey"/></visual><collision><origin rpy="0 0 0" xyz="0 0 0"/><geometry><mesh filename="package://pal_sea_arm_description/meshes/arm_tiago_pro/spherical-wrist/arm_5_link_collision.stl" scale="1 1 1"/></geometry></collision></link><!-- ARM 5 JOINT --><joint name="arm_right_5_joint" type="revolute"><!-- Check new limits --><origin rpy="-1.5707963267949 3.14 0" xyz="-0.0199999999999971 0.17011 -0.037110000000002"/><parent link="arm_right_4_link"/><child link="arm_right_5_link"/><axis xyz="0 0 1"/><limit effort="26" lower="-1.5707963267948966" upper="3.6651914291880923" velocity="3.95"/><safety_controller k_position="20" k_velocity="20" soft_lower_limit="-1.5007963267948965" soft_upper_limit="3.5951914291880924"/><dynamics damping="1.0" friction="1.0"/></joint><!-- ARM 6 LINK --><link name="arm_right_6_link"><inertial><origin rpy="0 0 0" xyz="0.031968 -0.0065097 -0.040676"/><mass value="1.378"/><inertia ixx="0.0011002" ixy="0.00012805" ixz="-5.6797E-06" iyy="0.0011658" iyz="5.4596E-07" izz="0.0011909"/></inertial><visual><origin rpy="0 0 0" xyz="0 0 0"/><geometry><mesh filename="package://pal_sea_arm_description/meshes/arm_tiago_pro/spherical-wrist/arm_6_link.stl" scale="1 1 1"/></geometry><material name="pal/DarkGrey"/></visual><collision><origin rpy="0 0 0" xyz="0 0 0"/><geometry><mesh filename="package://pal_sea_arm_description/meshes/arm_tiago_pro/spherical-wrist/arm_6_link_collision.stl" scale="1 1 1"/></geometry></collision></link><!-- ARM 6 JOINT --><joint name="arm_right_6_joint" type="revolute"><origin rpy="-1.5708 0 3.14" xyz="0 -0.0422 0.1654"/><parent link="arm_right_5_link"/><child link="arm_right_6_link"/><axis xyz="0 0 -1"/><limit effort="26" lower="-1.8849555921538759" upper="3.001966313430247" velocity="3.95"/><dynamics damping="1.0" friction="1.0"/><safety_controller k_position="20" k_velocity="20" soft_lower_limit="-1.8149555921538758" soft_upper_limit="2.931966313430247"/></joint><!-- ARM 7 LINK --><link name="arm_right_7_link"><inertial><origin rpy="0 0 0" xyz="-0.0016034 0.001194 0.0075583"/><mass value="0.1354"/><inertia ixx="5.0537E-05" ixy="-8.1184E-07" ixz="1.9023E-07" iyy="5.1762E-05" iyz="-3.2751E-07" izz="9.5274E-05"/></inertial><visual><origin rpy="0 0 0" xyz="0 0 0"/><geometry><mesh filename="package://pal_sea_arm_description/meshes/arm_tiago_pro/spherical-wrist/arm_7_link.stl" scale="1 1 1"/></geometry><material name="pal/DarkGrey"/></visual><collision><origin rpy="0 0 0" xyz="0 0 0"/><geometry><mesh filename="package://pal_sea_arm_description/meshes/arm_tiago_pro/spherical-wrist/arm_7_link_collision.stl" scale="1 1 1"/></geometry></collision></link><!-- ARM 7 JOINT --><joint name="arm_right_7_joint" type="revolute"><origin rpy="1.5708 0 0" xyz="0.07 -0.0534 -0.0422"/><parent link="arm_right_6_link"/><child link="arm_right_7_link"/><axis xyz="0 0 1"/><limit effort="26" lower="-2.6179938779914944" upper="2.6179938779914944" velocity="3.95"/><dynamics damping="1.0" friction="1.0"/><safety_controller k_position="20" k_velocity="20" soft_lower_limit="-2.5479938779914946" soft_upper_limit="2.5479938779914946"/></joint><!--***********************--><!--        TOOL           --><!--***********************--><link name="arm_right_tool_link"/><joint name="arm_right_tool_joint" type="fixed"><parent link="arm_right_7_link"/><child link="arm_right_tool_link"/><origin rpy="0 0 0" xyz="0 0 0.017"/></joint><!-- GAZEBO PROPERTIES --><gazebo reference="arm_right_1_link"><material>Gazebo/DarkGrey</material><mu1>0.9</mu1><mu2>0.9</mu2></gazebo><gazebo reference="arm_right_1_joint"><implicitSpringDamper>1</implicitSpringDamper></gazebo><gazebo reference="arm_right_2_link"><material>Gazebo/DarkGrey</material><mu1>0.9</mu1><mu2>0.9</mu2></gazebo><gazebo reference="arm_right_2_joint"><implicitSpringDamper>1</implicitSpringDamper></gazebo><gazebo reference="arm_right_3_link"><material>Gazebo/DarkGrey</material><mu1>0.9</mu1><mu2>0.9</mu2></gazebo><gazebo reference="arm_right_3_joint"><implicitSpringDamper>1</implicitSpringDamper></gazebo><gazebo reference="arm_right_4_link"><material>Gazebo/DarkGrey</material><mu1>0.9</mu1><mu2>0.9</mu2></gazebo><gazebo reference="arm_right_4_joint"><implicitSpringDamper>1</implicitSpringDamper></gazebo><gazebo reference="arm_right_5_link"><material>Gazebo/DarkGrey</material><mu1>0.9</mu1><mu2>0.9</mu2></gazebo><gazebo reference="arm_right_5_joint"><implicitSpringDamper>1</implicitSpringDamper></gazebo><gazebo reference="arm_right_6_link"><material>Gazebo/DarkGrey</material><mu1>0.9</mu1><mu2>0.9</mu2></gazebo><gazebo reference="arm_right_6_joint"><implicitSpringDamper>1</implicitSpringDamper></gazebo><gazebo reference="arm_right_7_link"><material>Gazebo/DarkGrey</material><mu1>0.9</mu1><mu2>0.9</mu2></gazebo><gazebo reference="arm_right_7_joint"><implicitSpringDamper>1</implicitSpringDamper><provideFeedback>1</provideFeedback></gazebo><gazebo reference="arm_right_tool_link"><material>Gazebo/DarkGrey</material><mu1>0.9</mu1><mu2>0.9</mu2></gazebo><link name="gripper_right_pal_atc_base_link"><inertial><origin rpy="0 0 0" xyz="-0.00005 -0.00001 0.04654"/><mass value="0.70250"/><inertia ixx="0.00060" ixy="0.0" ixz="0.0" iyy="0.00061" iyz="0.0" izz="0.00052"/></inertial><visual><origin rpy="0 0 0" xyz="0 0 0"/><geometry><mesh filename="package://pal_atc_description/meshes/pal_atc_base_link.stl"/></geometry><material name="pal/DarkGrey"/></visual><collision><origin rpy="0 0 0" xyz="0 0 0.03995"/><geometry><cylinder length="0.0799" radius="0.0375"/></geometry></collision></link><joint name="gripper_right_pal_atc_base_joint" type="fixed"><origin rpy="0 0 0" xyz="0 0 0"/><parent link="wrist_right_ft_tool_link"/><child link="gripper_right_pal_atc_base_link"/><axis xyz="0 0 0"/></joint><link name="gripper_right_tool_mount"><inertial><origin rpy="0 0 0" xyz="-0.00013 -0.00004 -0.01534"/><mass value="0.11421"/><inertia ixx="0.00001" ixy="0.0" ixz="0.0" iyy="0.00001" iyz="0.0" izz="0.00002"/></inertial><visual><origin rpy="0 0 0" xyz="0 0 0"/><geometry><mesh filename="package://pal_atc_description/meshes/tool_mount.stl"/></geometry><material name="pal/DarkGrey"/></visual><collision><origin rpy="0 0 0" xyz="0 0 0"/><geometry><cylinder length="0.0256" radius="0.0245"/></geometry></collision></link><joint name="gripper_right_tool_mount_joint" type="continuous"><origin rpy="0 0 0" xyz="0 0 0.10325"/><parent link="gripper_right_pal_atc_base_link"/><child link="gripper_right_tool_mount"/><dynamics damping="0.03" friction="0.1"/><axis xyz="0 0 1"/></joint><link name="gripper_right_tool_holder"><inertial><origin rpy="0 0 0" xyz="-0.00005 0.0 -0.03737"/><mass value="0.17802"/><inertia ixx="0.00006" ixy="0.0" ixz="0.0" iyy="0.00006" iyz="0.0" izz="0.00004"/></inertial><visual><origin rpy="0 0 0" xyz="0 0 0"/><geometry><mesh filename="package://pal_atc_description/meshes/tool_holder.stl"/></geometry><material name=""><color rgba="0.827450980392157 0.83921568627451 0.827450980392157 1"/></material></visual><collision><origin rpy="0 0 0" xyz="0 0 0"/><geometry><mesh filename="package://pal_atc_description/meshes/tool_holder.stl"/></geometry></collision></link><joint name="gripper_right_tool_holder_joint" type="fixed"><origin rpy="0 0 0" xyz="0 0 0.038678"/><parent link="gripper_right_tool_mount"/><child link="gripper_right_tool_holder"/><axis xyz="0 0 0"/></joint><!-- Gazebo config --><gazebo reference="gripper_right_pal_atc_base_link"><material>Gazebo/DarkGrey</material><mu1>0.9</mu1><mu2>0.9</mu2></gazebo><gazebo reference="gripper_right_tool_mount"><material>Gazebo/DarkGrey</material><mu1>0.9</mu1><mu2>0.9</mu2></gazebo><gazebo reference="gripper_right_tool_holder"><material>Gazebo/DarkGrey</material><mu1>0.9</mu1><mu2>0.9</mu2></gazebo><gazebo reference="gripper_right_tool_mount_joint"><provideFeedback>1</provideFeedback></gazebo><!-- PAL Pro Prototype --><!-- <xacro:if value="${type == 'pal-pro-gripper-prototype'}">
      <xacro:include filename="$(find pal_pro_gripper_description)/urdf/pro_gripper_prototype.urdf.xacro" />
      <xacro:pal_pro_gripper_prototype name="${name}" parent="${parent}">
        <origin xyz="0.052 0.0 0.0" rpy="0 ${90 * deg_to_rad} 0"/>
      </xacro:pal_pro_gripper_prototype>
    </xacro:if> --><!-- Custom --><!-- <xacro:if value="${type == 'custom' and not is_dual}">
    <xacro:include filename="$(find custom_ee_description)/urdf/end-effector.urdf.xacro" />
    <xacro:end_effector parent="${parent}">
      <origin xyz="0.0 0 0" rpy="0 0 0"/>
    </xacro:end_effector>
  </xacro:if> --><!-- Custom dual--><!-- <xacro:if value="${type == 'custom' and is_dual}"> --><!-- If right --><!-- <xacro:if value="${reflect == 1}">
    <xacro:include filename="$(find custom_dual_ee_description)/urdf/end-effector-right.urdf.xacro" />
    <xacro:end_effector_right parent="${parent}">
      <origin xyz="0.0 0 0" rpy="0 0 0"/>
    </xacro:end_effector_right>
    </xacro:if> --><!-- If left --><!-- <xacro:if value="${reflect == -1}">
    <xacro:include filename="$(find custom_dual_ee_description)/urdf/end-effector-left.urdf.xacro" />
    <xacro:end_effector_left parent="${parent}">
      <origin xyz="0.0 0 0" rpy="0 0 0"/>
    </xacro:end_effector_left>
    </xacro:if>
  </xacro:if> --><!-- FT DEFINITION --><!-- Gazebo reference --><gazebo reference="wrist_right_ft_link"><material>Gazebo/DarkGrey</material><mu1>0.9</mu1><mu2>0.9</mu2></gazebo><!-- Base link --><link name="wrist_right_ft_sensor_base_link"><inertial><origin rpy="0 0 0" xyz="-0.0004587 0.00019238 0.011064"/><mass value="0.077013"/><inertia ixx="3.7638E-05" ixy="6.5947E-07" ixz="1.7831E-07" iyy="4.0868E-05" iyz="3.7283E-08" izz="7.4732E-05"/></inertial><visual><origin rpy="0 0 0" xyz="0 0 0"/><geometry><mesh filename="package://pal_urdf_utils//meshes/ft_sensors/ati_ft_sensor.stl"/></geometry><material name="pal/DarkGrey"/></visual><collision><origin rpy="0 0 0" xyz="0 0 0.0229"/><geometry><cylinder length="0.045898" radius="0.0375"/></geometry></collision></link><gazebo reference="wrist_right_ft_sensor_base_link"><material>Gazebo/DarkGrey</material><mu1>0.9</mu1><mu2>0.9</mu2></gazebo><joint name="wrist_right_ft_sensor_base_joint" type="fixed"><parent link="arm_right_tool_link"/><child link="wrist_right_ft_sensor_base_link"/><axis xyz="0 0 0"/></joint><!-- FT sensor link; the inertia and visual needs to exist for the ft sensor gazebo plugin to work --><link name="wrist_right_ft_sensor_link"><inertial><origin rpy="0 0 0" xyz="-0.0010016 0.00099433 -0.0081076"/><mass value="0.068524"/><inertia ixx="1.1292E-05" ixy="1.0587E-06" ixz="-2.5242E-07" iyy="1.1125E-05" iyz="2.4515E-07" izz="1.9659E-05"/></inertial><visual><origin rpy="0 0 0" xyz="0 0 0.01"/><geometry><cylinder length="0.01" radius="0.03"/></geometry><material name="pal/DarkGrey"/></visual><collision><origin rpy="0 0 0" xyz="0 0 0.01"/><geometry><cylinder length="0.01" radius="0.03"/></geometry></collision></link><gazebo reference="wrist_right_ft_sensor_link"><material>Gazebo/DarkGrey</material><mu1>0.9</mu1><mu2>0.9</mu2></gazebo><joint name="wrist_right_ft_sensor_joint" type="fixed"><origin rpy="0 0 0" xyz="0 0 0.033998"/><parent link="wrist_right_ft_sensor_base_link"/><child link="wrist_right_ft_sensor_link"/><axis xyz="0 0 0"/></joint><!-- FT out link; the inertia and visual needs to exist for the ft sensor gazebo plugin to work --><link name="wrist_right_ft_tool_link"><inertial><origin rpy="0 0 0" xyz="-0.0018748 0.0028583 -0.0014148"/><mass value="0.082473"/><inertia ixx="1.74E-05" ixy="-1.3726E-06" ixz="-1.6642E-07" iyy="2.0744E-05" iyz="-2.9811E-09" izz="3.6674E-05"/></inertial><visual><origin rpy="0 0 0" xyz="0 0 -0.01"/><geometry><cylinder length="0.01" radius="0.03"/></geometry><material name="pal/DarkGrey"/></visual><collision><origin rpy="0 0 0" xyz="0 0 -0.01"/><geometry><cylinder length="0.01" radius="0.03"/></geometry></collision></link><gazebo reference="wrist_right_ft_tool_link"><material>Gazebo/DarkGrey</material><mu1>0.9</mu1><mu2>0.9</mu2></gazebo><joint name="wrist_right_ft_tool_joint" type="fixed"><origin rpy="0 0 0" xyz="0 0 0.039998"/><parent link="wrist_right_ft_sensor_base_link"/><child link="wrist_right_ft_tool_link"/><axis xyz="0 0 0"/></joint><gazebo reference="wrist_right_ft_sensor_joint"><preserveFixedJoint>true</preserveFixedJoint><!-- in case this is in a fixed joint --><sensor name="wrist_right_ft_sensor" type="force_torque"><update_rate>30</update_rate><visualize>true</visualize><force_torque><frame>child</frame><measure_direction>child_to_parent</measure_direction></force_torque></sensor></gazebo><!-- TODO--><!-- TODO Compute real wheel max velocity --><!-- CAN system --><ros2_control name="ros2_control_tiago_pro_system_can" rw_rate="100" type="system"><!-- Execution env config --><hardware><plugin>robot_control/RobotControl</plugin><param name="group">can</param></hardware><joint name="wheel_front_right_joint"><command_interface name="velocity"/><state_interface name="position"/></joint><transmission name="wheel_front_right_trans"><plugin>transmission_interface/SimpleTransmission</plugin><actuator name="wheel_front_right_actuator" role="actuator1"/><joint name="wheel_front_right_joint" role="joint1"><mechanical_reduction>1.0</mechanical_reduction></joint></transmission><joint name="wheel_front_left_joint"><command_interface name="velocity"/><state_interface name="position"/></joint><transmission name="wheel_front_left_trans"><plugin>transmission_interface/SimpleTransmission</plugin><actuator name="wheel_front_left_actuator" role="actuator1"/><joint name="wheel_front_left_joint" role="joint1"><mechanical_reduction>1.0</mechanical_reduction></joint></transmission><joint name="wheel_rear_right_joint"><command_interface name="velocity"/><state_interface name="position"/></joint><transmission name="wheel_rear_right_trans"><plugin>transmission_interface/SimpleTransmission</plugin><actuator name="wheel_rear_right_actuator" role="actuator1"/><joint name="wheel_rear_right_joint" role="joint1"><mechanical_reduction>1.0</mechanical_reduction></joint></transmission><joint name="wheel_rear_left_joint"><command_interface name="velocity"/><state_interface name="position"/></joint><transmission name="wheel_rear_left_trans"><plugin>transmission_interface/SimpleTransmission</plugin><actuator name="wheel_rear_left_actuator" role="actuator1"/><joint name="wheel_rear_left_joint" role="joint1"><mechanical_reduction>1.0</mechanical_reduction></joint></transmission></ros2_control><!-- Dynamixels system --><ros2_control name="ros2_control_tiago_pro_system_dynamixel" rw_rate="100" type="system"><hardware><plugin>robot_control/RobotControl</plugin><param name="group">dynamixel</param></hardware><joint name="head_1_joint"><command_interface name="position"/><state_interface name="position"/><state_interface name="velocity"/><state_interface name="effort"/></joint><transmission name="head_1_trans"><plugin>transmission_interface/SimpleTransmission</plugin><actuator name="head_1_actuator" role="actuator1"/><joint name="head_1_joint" role="joint1"><offset>-0.00444984</offset><mechanicalReduction>1</mechanicalReduction></joint></transmission><joint name="head_2_joint"><command_interface name="position"/><state_interface name="position"/><state_interface name="velocity"/><state_interface name="effort"/></joint><transmission name="head_2_trans"><plugin>transmission_interface/SimpleTransmission</plugin><actuator name="head_2_actuator" role="actuator1"/><joint name="head_2_joint" role="joint1"><offset>0.0541432</offset><mechanicalReduction>1</mechanicalReduction></joint></transmission></ros2_control><!-- Ethercat system --><ros2_control name="ros2_control_tiago_pro_system_ethercat" rw_rate="1000" type="system"><hardware><plugin>robot_control/RobotControl</plugin><param name="group">ethercat</param><param name="error_protection">true</param><param name="idle_mode_on_stop">true</param><param name="expose_collision_interface">true</param><param name="expose_safety_interface">true</param></hardware><joint name="arm_left_1_joint"><command_interface name="position"/><command_interface name="velocity"/><command_interface name="effort"/><state_interface name="position"/><state_interface name="velocity"/><state_interface name="effort"/><state_interface name="torque"/><state_interface name="absolute_position"/></joint><transmission name="arm_left_1_trans"><plugin>sea_transmissions/SeaSimpleTransmission</plugin><actuator name="arm_left_1_actuator" role="actuator1"/><joint name="arm_left_1_joint" role="joint1"><offset>0.0</offset><mechanical_reduction>121.0</mechanical_reduction></joint><param name="sea_data_type">sea_data</param></transmission><joint name="arm_left_2_joint"><command_interface name="position"/><command_interface name="velocity"/><command_interface name="effort"/><state_interface name="position"/><state_interface name="velocity"/><state_interface name="effort"/><state_interface name="torque"/><state_interface name="absolute_position"/></joint><transmission name="arm_left_2_trans"><plugin>sea_transmissions/SeaSimpleTransmission</plugin><actuator name="arm_left_2_actuator" role="actuator1"/><joint name="arm_left_2_joint" role="joint1"><offset>0.0</offset><mechanical_reduction>121.0</mechanical_reduction></joint><param name="sea_data_type">sea_data</param></transmission><joint name="arm_left_3_joint"><command_interface name="position"/><command_interface name="velocity"/><command_interface name="effort"/><state_interface name="position"/><state_interface name="velocity"/><state_interface name="effort"/><state_interface name="torque"/><state_interface name="absolute_position"/></joint><transmission name="arm_left_3_trans"><plugin>sea_transmissions/SeaSimpleTransmission</plugin><actuator name="arm_left_3_actuator" role="actuator1"/><joint name="arm_left_3_joint" role="joint1"><offset>0.0</offset><mechanical_reduction>101.0</mechanical_reduction></joint><param name="sea_data_type">sea_data</param></transmission><joint name="arm_left_4_joint"><command_interface name="position"/><command_interface name="velocity"/><command_interface name="effort"/><state_interface name="position"/><state_interface name="velocity"/><state_interface name="effort"/><state_interface name="torque"/><state_interface name="absolute_position"/></joint><transmission name="arm_left_4_trans"><plugin>sea_transmissions/SeaSimpleTransmission</plugin><actuator name="arm_left_4_actuator" role="actuator1"/><joint name="arm_left_4_joint" role="joint1"><offset>0.0</offset><mechanical_reduction>101.0</mechanical_reduction></joint><param name="sea_data_type">sea_data</param></transmission><joint name="arm_left_5_joint"><command_interface name="position"/><command_interface name="velocity"/><command_interface name="effort"/><state_interface name="position"/><state_interface name="velocity"/><state_interface name="effort"/><state_interface name="torque"/><state_interface name="absolute_position"/></joint><transmission name="arm_left_5_trans"><plugin>sea_transmissions/SeaSimpleTransmission</plugin><actuator name="arm_left_5_actuator" role="actuator1"/><joint name="arm_left_5_joint" role="joint1"><offset>0.0</offset><mechanical_reduction>101.0</mechanical_reduction></joint><param name="sea_data_type">sea_data</param></transmission><joint name="arm_left_6_joint"><command_interface name="position"/><command_interface name="velocity"/><command_interface name="effort"/><state_interface name="position"/><state_interface name="velocity"/><state_interface name="effort"/><state_interface name="torque"/><state_interface name="absolute_position"/></joint><transmission name="arm_left_6_trans"><plugin>sea_transmissions/SeaSimpleTransmission</plugin><actuator name="arm_left_6_actuator" role="actuator1"/><joint name="arm_left_6_joint" role="joint1"><offset>0.0</offset><mechanical_reduction>101.0</mechanical_reduction></joint><param name="sea_data_type">sea_data</param></transmission><joint name="arm_left_7_joint"><command_interface name="position"/><command_interface name="velocity"/><command_interface name="effort"/><state_interface name="position"/><state_interface name="velocity"/><state_interface name="effort"/><state_interface name="torque"/><state_interface name="absolute_position"/></joint><transmission name="arm_left_7_trans"><plugin>sea_transmissions/SeaSimpleTransmission</plugin><actuator name="arm_left_7_actuator" role="actuator1"/><joint name="arm_left_7_joint" role="joint1"><offset>0.0</offset><mechanical_reduction>101.0</mechanical_reduction></joint><param name="sea_data_type">sea_data</param></transmission><joint name="gripper_left_finger_joint"><command_interface name="position"/><state_interface name="position"><param name="initial_value">0.07</param></state_interface><state_interface name="velocity"/><state_interface name="effort"/></joint><joint name="gripper_left_outer_finger_right_joint"><param name="mimic">gripper_left_finger_joint</param><param name="multiplier">-8.28</param></joint><joint name="gripper_left_inner_finger_right_joint"><param name="mimic">gripper_left_finger_joint</param><param name="multiplier">-8.28</param></joint><joint name="gripper_left_fingertip_right_joint"><param name="mimic">gripper_left_finger_joint</param><param name="multiplier">8.28</param></joint><joint name="gripper_left_finger_right_joint"><param name="mimic">gripper_left_finger_joint</param><param name="multiplier">0.22</param></joint><joint name="gripper_left_outer_finger_left_joint"><param name="mimic">gripper_left_finger_joint</param><param name="multiplier">-8.28</param></joint><joint name="gripper_left_inner_finger_left_joint"><param name="mimic">gripper_left_finger_joint</param><param name="multiplier">-8.28</param></joint><joint name="gripper_left_fingertip_left_joint"><param name="mimic">gripper_left_finger_joint</param><param name="multiplier">8.28</param></joint><transmission name="gripper_left_finger_trans"><plugin>pal_pro_gripper_transmissions/PalGripperTransmission</plugin><actuator name="gripper_left_finger_actuator" role="actuator1"/><joint name="gripper_left_finger_joint" role="joint1"><mechanical_reduction>0.001343799</mechanical_reduction></joint></transmission><joint name="arm_right_1_joint"><command_interface name="position"/><command_interface name="velocity"/><command_interface name="effort"/><state_interface name="position"/><state_interface name="velocity"/><state_interface name="effort"/><state_interface name="torque"/><state_interface name="absolute_position"/></joint><transmission name="arm_right_1_trans"><plugin>sea_transmissions/SeaSimpleTransmission</plugin><actuator name="arm_right_1_actuator" role="actuator1"/><joint name="arm_right_1_joint" role="joint1"><offset>-0.0331023</offset><mechanical_reduction>121.0</mechanical_reduction></joint><param name="sea_data_type">sea_data</param></transmission><joint name="arm_right_2_joint"><command_interface name="position"/><command_interface name="velocity"/><command_interface name="effort"/><state_interface name="position"/><state_interface name="velocity"/><state_interface name="effort"/><state_interface name="torque"/><state_interface name="absolute_position"/></joint><transmission name="arm_right_2_trans"><plugin>sea_transmissions/SeaSimpleTransmission</plugin><actuator name="arm_right_2_actuator" role="actuator1"/><joint name="arm_right_2_joint" role="joint1"><offset>-0.0368194</offset><mechanical_reduction>121.0</mechanical_reduction></joint><param name="sea_data_type">sea_data</param></transmission><joint name="arm_right_3_joint"><command_interface name="position"/><command_interface name="velocity"/><command_interface name="effort"/><state_interface name="position"/><state_interface name="velocity"/><state_interface name="effort"/><state_interface name="torque"/><state_interface name="absolute_position"/></joint><transmission name="arm_right_3_trans"><plugin>sea_transmissions/SeaSimpleTransmission</plugin><actuator name="arm_right_3_actuator" role="actuator1"/><joint name="arm_right_3_joint" role="joint1"><offset>0.0246666</offset><mechanical_reduction>101.0</mechanical_reduction></joint><param name="sea_data_type">sea_data</param></transmission><joint name="arm_right_4_joint"><command_interface name="position"/><command_interface name="velocity"/><command_interface name="effort"/><state_interface name="position"/><state_interface name="velocity"/><state_interface name="effort"/><state_interface name="torque"/><state_interface name="absolute_position"/></joint><transmission name="arm_right_4_trans"><plugin>sea_transmissions/SeaSimpleTransmission</plugin><actuator name="arm_right_4_actuator" role="actuator1"/><joint name="arm_right_4_joint" role="joint1"><offset>0.0024465</offset><mechanical_reduction>101.0</mechanical_reduction></joint><param name="sea_data_type">sea_data</param></transmission><joint name="arm_right_5_joint"><command_interface name="position"/><command_interface name="velocity"/><command_interface name="effort"/><state_interface name="position"/><state_interface name="velocity"/><state_interface name="effort"/><state_interface name="torque"/><state_interface name="absolute_position"/></joint><transmission name="arm_right_5_trans"><plugin>sea_transmissions/SeaSimpleTransmission</plugin><actuator name="arm_right_5_actuator" role="actuator1"/><joint name="arm_right_5_joint" role="joint1"><offset>-0.0257308</offset><mechanical_reduction>101.0</mechanical_reduction></joint><param name="sea_data_type">sea_data</param></transmission><joint name="arm_right_6_joint"><command_interface name="position"/><command_interface name="velocity"/><command_interface name="effort"/><state_interface name="position"/><state_interface name="velocity"/><state_interface name="effort"/><state_interface name="torque"/><state_interface name="absolute_position"/></joint><transmission name="arm_right_6_trans"><plugin>sea_transmissions/SeaSimpleTransmission</plugin><actuator name="arm_right_6_actuator" role="actuator1"/><joint name="arm_right_6_joint" role="joint1"><offset>-0.0162585</offset><mechanical_reduction>101.0</mechanical_reduction></joint><param name="sea_data_type">sea_data</param></transmission><joint name="arm_right_7_joint"><command_interface name="position"/><command_interface name="velocity"/><command_interface name="effort"/><state_interface name="position"/><state_interface name="velocity"/><state_interface name="effort"/><state_interface name="torque"/><state_interface name="absolute_position"/></joint><transmission name="arm_right_7_trans"><plugin>sea_transmissions/SeaSimpleTransmission</plugin><actuator name="arm_right_7_actuator" role="actuator1"/><joint name="arm_right_7_joint" role="joint1"><offset>0.0</offset><mechanical_reduction>101.0</mechanical_reduction></joint><param name="sea_data_type">sea_data</param></transmission><sensor name="wrist_right_ft_sensor"><state_interface name="force.x"/><state_interface name="force.y"/><state_interface name="force.z"/><state_interface name="torque.x"/><state_interface name="torque.y"/><state_interface name="torque.z"/></sensor><joint name="gripper_right_tool_mount_joint"><command_interface name="effort"/><!-- TODO: Remove when moving to Gazebo Harmonic or ROS 2 Jazzy --><!-- Multiple command interfaces not working on Gazebo Fortress --><!-- https://github.com/ros-controls/gz_ros2_control/issues/182 --><command_interface name="velocity"/><command_interface name="position"/><state_interface name="position"/><state_interface name="velocity"/><state_interface name="effort"/></joint><transmission name="gripper_right_tool_mount_trans"><plugin>transmission_interface/SimpleTransmission</plugin><actuator name="gripper_right_tool_mount_actuator" role="actuator1"/><joint name="gripper_right_tool_mount_joint" role="joint1"><mechanical_reduction>1.0</mechanical_reduction></joint></transmission><joint name="torso_lift_joint"><command_interface name="position"/><command_interface name="velocity"/><state_interface name="position"/><state_interface name="velocity"/><state_interface name="effort"/></joint><transmission name="torso_lift_trans"><plugin>transmission_interface/SimpleTransmission</plugin><actuator name="torso_lift_actuator" role="actuator1"/><joint name="torso_lift_joint" role="joint1"><mechanical_reduction>1.0</mechanical_reduction><offset>0.0</offset></joint></transmission></ros2_control><!-- To test! --><!-- <xacro:if value="${end_effector_teleop_right == 'allegro-hand'}">
        <xacro:allegro_ros2_control side="right" allegro_can="can2" pid_controllers="$(arg pid_controllers)"/>
      </xacro:if>
      <xacro:if value="${end_effector_teleop_left == 'allegro-hand'}">
        <xacro:allegro_ros2_control side="left" allegro_can="can1" pid_controllers="$(arg pid_controllers)"/>
      </xacro:if> --></robot>